Workbook

Sheet ProjecaoAreas
H2: Custo Safra 16/17
B4: # Resumo por cultura | H4: # Resumo por cultura e fazenda
B6: Cultura | C6: R$ / ha | D6: Área | E6: Custo Projetado | F6: % | H6: Fazenda | I6: Cultura | J6: Area | K6: Custo Projetado | L6: Perc%
B7: SOJA CONVENCIONAL | C7: 2000 | D7: =SUMIF($I$7:$I$45,B7,$J$7:$J$45) -> 12800 | E7: =SUMIF($I$7:$I$45,B7,$K$7:$K$45) -> 25600000 | F7: =E7/E$18 -> 0.14856254 | H7: 01-FAZENDA SAUDADES | I7: SOJA RR | J7: =2000+9868 -> 11868 | K7: =SUMIF($B$7:$B$17,I7,$C$7:$C$17)*J7 -> 23736000 | L7: =K7/(SUMIF($H$7:$H$46,H7,$K$7:$K$46)) -> 0.1847217
B8: SOJA RR | C8: 2000 | D8: =SUMIF($I$7:$I$45,B8,$J$7:$J$45) -> 23853 | E8: =SUMIF($I$7:$I$45,B8,$K$7:$K$45) -> 47706000 | F8: =E8/E$18 -> 0.27684862 | H8: 01-FAZENDA SAUDADES | I8: SOJA SEMENTE CONVENCIONAL | J8: 1000 | K8: =SUMIF($B$7:$B$17,I8,$C$7:$C$17)*J8 -> 2000000 | L8: =K8/(SUMIF($H$7:$H$46,H8,$K$7:$K$46)) -> 0.015564687
B9: SOJA SEMENTE RR | C9: 2000 | D9: =SUMIF($I$7:$I$45,B9,$J$7:$J$45) -> 3500 | E9: =SUMIF($I$7:$I$45,B9,$K$7:$K$45) -> 7000000 | F9: =E9/E$18 -> 0.04062257 | H9: 01-FAZENDA SAUDADES | I9: MILHO EM GRAOS | J9: 12000 | K9: =SUMIF($B$7:$B$17,I9,$C$7:$C$17)*J9 -> 14400000 | L9: =K9/(SUMIF($H$7:$H$46,H9,$K$7:$K$46)) -> 0.11206575
B10: SOJA SEMENTE CONVENCIONAL | C10: 2000 | D10: =SUMIF($I$7:$I$45,B10,$J$7:$J$45) -> 1000 | E10: =SUMIF($I$7:$I$45,B10,$K$7:$K$45) -> 2000000 | F10: =E10/E$18 -> 0.011606449 | H10: 01-FAZENDA SAUDADES | I10: ALGODAO | J10: 8000 | K10: =SUMIF($B$7:$B$17,I10,$C$7:$C$17)*J10 -> 60000000 | L10: =K10/(SUMIF($H$7:$H$46,H10,$K$7:$K$46)) -> 0.46694061
B11: MILHO EM GRAOS | C11: 1200 | D11: =SUMIF($I$7:$I$45,B11,$J$7:$J$45) -> 22460 | E11: =SUMIF($I$7:$I$45,B11,$K$7:$K$45) -> 26952000 | F11: =E11/E$18 -> 0.1564085 | H11: 01-FAZENDA SAUDADES | I11: SOJA CONVENCIONAL | J11: =11000 -> 11000 | K11: =SUMIF($B$7:$B$17,I11,$C$7:$C$17)*J11 -> 22000000 | L11: =K11/(SUMIF($H$7:$H$46,H11,$K$7:$K$46)) -> 0.17121156
B12: MILHO SILAGEM | C12: 1200 | D12: =SUMIF($I$7:$I$45,B12,$J$7:$J$45) -> 300 | E12: =SUMIF($I$7:$I$45,B12,$K$7:$K$45) -> 360000 | F12: =E12/E$18 -> 0.0020891607 | H12: 01-FAZENDA SAUDADES | I12: SOJA SEMENTE RR | J12: =1000+2000 -> 3000 | K12: =SUMIF($B$7:$B$17,I12,$C$7:$C$17)*J12 -> 6000000 | L12: =K12/(SUMIF($H$7:$H$46,H12,$K$7:$K$46)) -> 0.046694061
B13: ALGODAO | C13: 7500 | D13: =SUMIF($I$7:$I$45,B13,$J$7:$J$45) -> 8000 | E13: =SUMIF($I$7:$I$45,B13,$K$7:$K$45) -> 60000000 | F13: =E13/E$18 -> 0.34819346 | H13: 01-FAZENDA SAUDADES | I13: MILHO SILAGEM | J13: 300 | K13: =SUMIF($B$7:$B$17,I13,$C$7:$C$17)*J13 -> 360000 | L13: =K13/(SUMIF($H$7:$H$46,H13,$K$7:$K$46)) -> 0.0028016436
B14: GADO | C14: 500 | D14: =SUMIF($I$7:$I$45,B14,$J$7:$J$45) -> 0 | E14: =SUMIF($I$7:$I$45,B14,$K$7:$K$45) -> 0 | F14: =E14/E$18 -> 0 | H14: 02-FAZENDA JK | I14: SOJA RR | J14: 4315 | K14: =SUMIF($B$7:$B$17,I14,$C$7:$C$17)*J14 -> 8630000 | L14: =K14/(SUMIF($H$7:$H$46,H14,$K$7:$K$46)) -> 0.49569213
B15: ARROZ | C15: 1500 | D15: =SUMIF($I$7:$I$45,B15,$J$7:$J$45) -> 500 | E15: =SUMIF($I$7:$I$45,B15,$K$7:$K$45) -> 750000 | F15: =E15/E$18 -> 0.0043524182 | H15: 02-FAZENDA JK | I15: SOJA CONVENCIONAL | J15: 1300 | K15: =SUMIF($B$7:$B$17,I15,$C$7:$C$17)*J15 -> 2600000 | L15: =K15/(SUMIF($H$7:$H$46,H15,$K$7:$K$46)) -> 0.14933946
B16: BRAQUIARIA | C16: 200 | D16: =SUMIF($I$7:$I$45,B16,$J$7:$J$45) -> 0 | E16: =SUMIF($I$7:$I$45,B16,$K$7:$K$45) -> 0 | F16: =E16/E$18 -> 0 | H16: 02-FAZENDA JK | I16: MILHO EM GRAOS | J16: 5150 | K16: =SUMIF($B$7:$B$17,I16,$C$7:$C$17)*J16 -> 6180000 | L16: =K16/(SUMIF($H$7:$H$46,H16,$K$7:$K$46)) -> 0.35496841
B17: AREA EM ABERTURA | C17: 5000 | D17: =SUMIF($I$7:$I$45,B17,$J$7:$J$45) -> 390 | E17: =SUMIF($I$7:$I$45,B17,$K$7:$K$45) -> 1950000 | F17: =E17/E$18 -> 0.011316287 | H17: 02-FAZENDA JK | I17: SOJA SEMENTE RR | K17: =SUMIF($B$7:$B$17,I17,$C$7:$C$17)*J17 -> 0 | L17: =K17/(SUMIF($H$7:$H$46,H17,$K$7:$K$46)) -> 0
D18: =SUM(D7:D17) -> 72803 | E18: =SUM(E7:E17) -> 172318000 | F18: =E18/E18 -> 1 | H18: 02-FAZENDA JK | I18: SOJA SEMENTE CONVENCIONAL | K18: =SUMIF($B$7:$B$17,I18,$C$7:$C$17)*J18 -> 0 | L18: =K18/(SUMIF($H$7:$H$46,H18,$K$7:$K$46)) -> 0
H19: 03-FAZENDA JAQUELINE | I19: SOJA CONVENCIONAL | K19: =SUMIF($B$7:$B$17,I19,$C$7:$C$17)*J19 -> 0 | L19: =K19/(SUMIF($H$7:$H$46,H19,$K$7:$K$46)) -> 0
H20: 03-FAZENDA JAQUELINE | I20: MILHO EM GRAOS | J20: 2500 | K20: =SUMIF($B$7:$B$17,I20,$C$7:$C$17)*J20 -> 3000000 | L20: =K20/(SUMIF($H$7:$H$46,H20,$K$7:$K$46)) -> 0.375
H21: 03-FAZENDA JAQUELINE | I21: SOJA RR | J21: 2500 | K21: =SUMIF($B$7:$B$17,I21,$C$7:$C$17)*J21 -> 5000000 | L21: =K21/(SUMIF($H$7:$H$46,H21,$K$7:$K$46)) -> 0.625
H22: 03-FAZENDA JAQUELINE | I22: SOJA SEMENTE RR | K22: =SUMIF($B$7:$B$17,I22,$C$7:$C$17)*J22 -> 0 | L22: =K22/(SUMIF($H$7:$H$46,H22,$K$7:$K$46)) -> 0
H23: 04-FAZENDA PANTANAL | I23: MILHO EM GRAOS | J23: 360 | K23: =SUMIF($B$7:$B$17,I23,$C$7:$C$17)*J23 -> 432000 | L23: =K23/(SUMIF($H$7:$H$46,H23,$K$7:$K$46)) -> 0.077950198
H24: 04-FAZENDA PANTANAL | I24: SOJA RR | J24: 1580 | K24: =SUMIF($B$7:$B$17,I24,$C$7:$C$17)*J24 -> 3160000 | L24: =K24/(SUMIF($H$7:$H$46,H24,$K$7:$K$46)) -> 0.57019127
B25: # Resumo por fazenda | H25: 04-FAZENDA PANTANAL | I25: AREA EM ABERTURA | J25: 390 | K25: =SUMIF($B$7:$B$17,I25,$C$7:$C$17)*J25 -> 1950000 | L25: =K25/(SUMIF($H$7:$H$46,H25,$K$7:$K$46)) -> 0.35185853
K26: =SUMIF($B$7:$B$17,I26,$C$7:$C$17)*J26 -> 0
B27: Fazenda | D27: Área | E27: Custo Projetado | F27: % | H27: 05- FAZENDA VENTANIA | I27: SOJA RR | J27: 720 | K27: =SUMIF($B$7:$B$17,I27,$C$7:$C$17)*J27 -> 1440000 | L27: =K27/(SUMIF($H$7:$H$46,H27,$K$7:$K$46)) -> 0.6779661
B28: 01-FAZENDA SAUDADES | D28: =SUMIF($H$7:$H$45,B28,$J$7:$J$45) -> 47168 | E28: =SUMIF($H$7:$H$45,B28,$K$7:$K$45) -> 128496000 | F28: =E28/E$39 -> 0.74569111 | H28: 05- FAZENDA VENTANIA | I28: GADO | K28: =SUMIF($B$7:$B$17,I28,$C$7:$C$17)*J28 -> 0 | L28: =K28/(SUMIF($H$7:$H$46,H28,$K$7:$K$46)) -> 0
B29: 02-FAZENDA JK | D29: =SUMIF($H$7:$H$45,B29,$J$7:$J$45) -> 10765 | E29: =SUMIF($H$7:$H$45,B29,$K$7:$K$45) -> 17410000 | F29: =E29/E$39 -> 0.10103413 | K29: =SUMIF($B$7:$B$17,I29,$C$7:$C$17)*J29 -> 0
B30: 03-FAZENDA JAQUELINE | D30: =SUMIF($H$7:$H$45,B30,$J$7:$J$45) -> 5000 | E30: =SUMIF($H$7:$H$45,B30,$K$7:$K$45) -> 8000000 | F30: =E30/E$39 -> 0.046425794 | H30: 05- FAZENDA VENTANIA | I30: MILHO EM GRAOS | J30: 570 | K30: =SUMIF($B$7:$B$17,I30,$C$7:$C$17)*J30 -> 684000 | L30: =K30/(SUMIF($H$7:$H$46,H30,$K$7:$K$46)) -> 0.3220339
B31: 04-FAZENDA PANTANAL | D31: =SUMIF($H$7:$H$45,B31,$J$7:$J$45) -> 2330 | E31: =SUMIF($H$7:$H$45,B31,$K$7:$K$45) -> 5542000 | F31: =E31/E$39 -> 0.032161469 | H31: 06-FAZENDA CAPIVARA | I31: SOJA RR | J31: 660 | K31: =SUMIF($B$7:$B$17,I31,$C$7:$C$17)*J31 -> 1320000 | L31: =K31/(SUMIF($H$7:$H$46,H31,$K$7:$K$46)) -> 0.6626506
B32: 05- FAZENDA VENTANIA | D32: =SUMIF($H$7:$H$45,B32,$J$7:$J$45) -> 1290 | E32: =SUMIF($H$7:$H$45,B32,$K$7:$K$45) -> 2124000 | F32: =E32/E$39 -> 0.012326048 | H32: 06-FAZENDA CAPIVARA | I32: MILHO EM GRAOS | J32: 560 | K32: =SUMIF($B$7:$B$17,I32,$C$7:$C$17)*J32 -> 672000 | L32: =K32/(SUMIF($H$7:$H$46,H32,$K$7:$K$46)) -> 0.3373494
B33: 06-FAZENDA CAPIVARA | D33: =SUMIF($H$7:$H$45,B33,$J$7:$J$45) -> 1220 | E33: =SUMIF($H$7:$H$45,B33,$K$7:$K$45) -> 1992000 | F33: =E33/E$39 -> 0.011560023 | K33: =SUMIF($B$7:$B$17,I33,$C$7:$C$17)*J33 -> 0
B34: 07-CONF MASUTTI | D34: =SUMIF($H$7:$H$45,B34,$J$7:$J$45) -> 0 | E34: =SUMIF($H$7:$H$45,B34,$K$7:$K$45) -> 0 | F34: =E34/E$39 -> 0 | H34: 13-FAZENDA TRIUNFO | I34: SOJA RR | J34: 1450 | K34: =SUMIF($B$7:$B$17,I34,$C$7:$C$17)*J34 -> 2900000 | L34: =K34/(SUMIF($H$7:$H$46,H34,$K$7:$K$46)) -> 0.42335766
B35: 08-CONF SAUDADES | D35: =SUMIF($H$7:$H$45,B35,$J$7:$J$45) -> 0 | E35: =SUMIF($H$7:$H$45,B35,$K$7:$K$45) -> 0 | F35: =E35/E$39 -> 0 | H35: 13-FAZENDA TRIUNFO | I35: SOJA CONVENCIONAL | J35: 500 | K35: =SUMIF($B$7:$B$17,I35,$C$7:$C$17)*J35 -> 1000000 | L35: =K35/(SUMIF($H$7:$H$46,H35,$K$7:$K$46)) -> 0.1459854
B36: 11-FAZ MARABA | D36: =SUMIF($H$7:$H$45,B36,$J$7:$J$45) -> 0 | E36: =SUMIF($H$7:$H$45,B36,$K$7:$K$45) -> 0 | F36: =E36/E$39 -> 0 | H36: 13-FAZENDA TRIUNFO | I36: AREA EM ABERTURA | K36: =SUMIF($B$7:$B$17,I36,$C$7:$C$17)*J36 -> 0 | L36: =K36/(SUMIF($H$7:$H$46,H36,$K$7:$K$46)) -> 0
B37: 13-FAZENDA TRIUNFO | D37: =SUMIF($H$7:$H$45,B37,$J$7:$J$45) -> 3950 | E37: =SUMIF($H$7:$H$45,B37,$K$7:$K$45) -> 6850000 | F37: =E37/E$39 -> 0.039752086 | H37: 13-FAZENDA TRIUNFO | I37: MILHO EM GRAOS | J37: 1000 | K37: =SUMIF($B$7:$B$17,I37,$C$7:$C$17)*J37 -> 1200000 | L37: =K37/(SUMIF($H$7:$H$46,H37,$K$7:$K$46)) -> 0.17518248
B38: 14-FAZENDA PARAISO | D38: =SUMIF($H$7:$H$45,B38,$J$7:$J$45) -> 1080 | E38: =SUMIF($H$7:$H$45,B38,$K$7:$K$45) -> 1904000 | F38: =E38/E$39 -> 0.011049339 | H38: 13-FAZENDA TRIUNFO | I38: GADO | K38: =SUMIF($B$7:$B$17,I38,$C$7:$C$17)*J38 -> 0 | L38: =K38/(SUMIF($H$7:$H$46,H38,$K$7:$K$46)) -> 0
D39: =SUM(D28:D38) -> 72803 | E39: =SUM(E28:E38) -> 172318000 | F39: =E39/E39 -> 1 | H39: 13-FAZENDA TRIUNFO | I39: ARROZ | J39: 500 | K39: =SUMIF($B$7:$B$17,I39,$C$7:$C$17)*J39 -> 750000 | L39: =K39/(SUMIF($H$7:$H$46,H39,$K$7:$K$46)) -> 0.10948905
H40: 13-FAZENDA TRIUNFO | I40: SOJA SEMENTE RR | J40: 500 | K40: =SUMIF($B$7:$B$17,I40,$C$7:$C$17)*J40 -> 1000000 | L40: =K40/(SUMIF($H$7:$H$46,H40,$K$7:$K$46)) -> 0.1459854
H41: 07-CONF MASUTTI | I41: GADO | K41: =SUMIF($B$7:$B$17,I41,$C$7:$C$17)*J41 -> 0 | L41: 1
H42: 08-CONF SAUDADES | I42: GADO | K42: =SUMIF($B$7:$B$17,I42,$C$7:$C$17)*J42 -> 0 | L42: 1
H43: 11-FAZ MARABA | I43: GADO | K43: =SUMIF($B$7:$B$17,I43,$C$7:$C$17)*J43 -> 0 | L43: 1
...

Sheet ResumoCusto
B2: Grupo Masutti
B4: Claides Lazaretti Masutti e Outros
B6: Quadro - Projeção Custo Lavoura Safra 2016/2017
B7: =TODAY() -> 42601
B9: FILIAL | E9: 1 | F9: 2 | G9: 3 | H9: 4 | I9: 5 | J9: 6 | K9: 7 | L9: 8 | M9: 9 | N9: 10 | O9: 11 | Q9: CUSTO (ha)
E10: ÁREA | F10: DEFENSIVOS | G10: FERTILIZANTES | H10: COMBUSTIVEL | I10: FRETE | J10: FOLHA | K10: MANUT | L10: SEMENTE | M10: CONSUMO | N10: CALCARIO | O10: OUTROS | P10: TOTAL
E12: Total a Distribuir | F12: 10820 | G12: 0 | H12: 9000 | I12: 0 | J12: 15000 | K12: 8000 | L12: 2000 | M12: 3500 | N12: 0 | O12: 5700
O13: =+gerencial
B14: P R E V I S T O "U N I D A D E" | D14: 01-FAZENDA SAUDADES | E14: {=SUM(IF((ProjecaoAreas!$B$28:$B$38=ResumoCusto!D14),ProjecaoAreas!$D$28:$D$38))} -> 47168 | F14: {=(SUM(IF((Tabela_GM_PEDIDOS_2017_FIM[TIPO_GRUPO]=ResumoCusto!F$10)*(Tabela_GM_PEDIDOS_2017_FIM[FILIAL]=ResumoCusto!$D14),Tabela_GM_PEDIDOS_2017_FIM[VALOR_PAGAR]+Tabela_GM_PEDIDOS_2017_FIM[VC_FINANCEIRA]))/1000)+F12} -> 42995.749 | G14: {=(SUM(IF((Tabela_GM_PEDIDOS_2017_FIM[TIPO_GRUPO]=ResumoCusto!G$10)*(Tabela_GM_PEDIDOS_2017_FIM[FILIAL]=ResumoCusto!$D14),Tabela_GM_PEDIDOS_2017_FIM[VALOR_PAGAR]+Tabela_GM_PEDIDOS_2017_FIM[VC_FINANCEIRA]))/1000)+G12} -> 29482.667 | H14: {=(SUM(IF((Tabela_GM_PEDIDOS_2017_FIM[TIPO_GRUPO]=ResumoCusto!H$10)*(Tabela_GM_PEDIDOS_2017_FIM[FILIAL]=ResumoCusto!$D14),Tabela_GM_PEDIDOS_2017_FIM[VALOR_PAGAR]+Tabela_GM_PEDIDOS_2017_FIM[VC_FINANCEIRA]))/1000)+H12} -> 9000 | I14: =Frete!C8/1000 -> 9244.8183 | J14: {=(SUM(IF((Tabela_GM_PEDIDOS_2017_FIM[TIPO_GRUPO]=ResumoCusto!J$10)*(Tabela_GM_PEDIDOS_2017_FIM[FILIAL]=ResumoCusto!$D14),Tabela_GM_PEDIDOS_2017_FIM[VALOR_PAGAR]+Tabela_GM_PEDIDOS_2017_FIM[VC_FINANCEIRA]))/1000)+J12} -> 15000 | K14: {=(SUM(IF((Tabela_GM_PEDIDOS_2017_FIM[TIPO_GRUPO]=ResumoCusto!K$10)*(Tabela_GM_PEDIDOS_2017_FIM[FILIAL]=ResumoCusto!$D14),Tabela_GM_PEDIDOS_2017_FIM[VALOR_PAGAR]+Tabela_GM_PEDIDOS_2017_FIM[VC_FINANCEIRA]))/1000)+K12} -> 8000 | L14: {=(SUM(IF((Tabela_GM_PEDIDOS_2017_FIM[TIPO_GRUPO]=ResumoCusto!L$10)*(Tabela_GM_PEDIDOS_2017_FIM[FILIAL]=ResumoCusto!$D14),Tabela_GM_PEDIDOS_2017_FIM[VALOR_PAGAR]+Tabela_GM_PEDIDOS_2017_FIM[VC_FINANCEIRA]))/1000)+L12} -> 5344.4975 | M14: {=(SUM(IF((Tabela_GM_PEDIDOS_2017_FIM[TIPO_GRUPO]=ResumoCusto!M$10)*(Tabela_GM_PEDIDOS_2017_FIM[FILIAL]=ResumoCusto!$D14),Tabela_GM_PEDIDOS_2017_FIM[VALOR_PAGAR]+Tabela_GM_PEDIDOS_2017_FIM[VC_FINANCEIRA]))/1000)+M12} -> 3500 | N14: {=(SUM(IF((Tabela_GM_PEDIDOS_2017_FIM[TIPO_GRUPO]=ResumoCusto!N$10)*(Tabela_GM_PEDIDOS_2017_FIM[FILIAL]=ResumoCusto!$D14),Tabela_GM_PEDIDOS_2017_FIM[VALOR_PAGAR]+Tabela_GM_PEDIDOS_2017_FIM[VC_FINANCEIRA]))/1000)+N12} -> 289.332 | O14: {=(SUM(IF((Tabela_GM_PEDIDOS_2017_FIM[TIPO_GRUPO]=ResumoCusto!O$10)*(Tabela_GM_PEDIDOS_2017_FIM[FILIAL]=ResumoCusto!$D14),Tabela_GM_PEDIDOS_2017_FIM[VALOR_PAGAR]+Tabela_GM_PEDIDOS_2017_FIM[VC_FINANCEIRA]))/1000)+O12} -> 5736.3024 | P14: =SUM(F14:O14) -> 128593.37 | Q14: =P14/E14*1000 -> 2726.2841
D15: % Distribuição | F15: {=SUM(IF((ProjecaoAreas!$H$6:$H$46=ResumoCusto!$D$14)*(ProjecaoAreas!$I$6:$I$46=ResumoCusto!$D16),ProjecaoAreas!$L$6:$L$46))} -> 0.1847217 | G15: {=SUM(IF((ProjecaoAreas!$H$6:$H$46=ResumoCusto!$D$14)*(ProjecaoAreas!$I$6:$I$46=ResumoCusto!$D16),ProjecaoAreas!$L$6:$L$46))} -> 0.1847217 | H15: {=SUM(IF((ProjecaoAreas!$H$6:$H$46=ResumoCusto!$D$14)*(ProjecaoAreas!$I$6:$I$46=ResumoCusto!$D16),ProjecaoAreas!$L$6:$L$46))} -> 0.1847217 | I15: 0.347 | J15: {=SUM(IF((ProjecaoAreas!$H$6:$H$46=ResumoCusto!$D$14)*(ProjecaoAreas!$I$6:$I$46=ResumoCusto!$D16),ProjecaoAreas!$L$6:$L$46))} -> 0.1847217 | K15: {=SUM(IF((ProjecaoAreas!$H$6:$H$46=ResumoCusto!$D$14)*(ProjecaoAreas!$I$6:$I$46=ResumoCusto!$D16),ProjecaoAreas!$L$6:$L$46))} -> 0.1847217 | L15: {=SUM(IF((ProjecaoAreas!$H$6:$H$46=ResumoCusto!$D$14)*(ProjecaoAreas!$I$6:$I$46=ResumoCusto!$D16),ProjecaoAreas!$L$6:$L$46))} -> 0.1847217 | M15: {=SUM(IF((ProjecaoAreas!$H$6:$H$46=ResumoCusto!$D$14)*(ProjecaoAreas!$I$6:$I$46=ResumoCusto!$D16),ProjecaoAreas!$L$6:$L$46))} -> 0.1847217 | N15: {=SUM(IF((ProjecaoAreas!$H$6:$H$46=ResumoCusto!$D$14)*(ProjecaoAreas!$I$6:$I$46=ResumoCusto!$D16),ProjecaoAreas!$L$6:$L$46))} -> 0.1847217 | O15: {=SUM(IF((ProjecaoAreas!$H$6:$H$46=ResumoCusto!$D$14)*(ProjecaoAreas!$I$6:$I$46=ResumoCusto!$D16),ProjecaoAreas!$L$6:$L$46))} -> 0.1847217
D16: SOJA RR | E16: {=SUM(IF((ProjecaoAreas!$H$6:$H$46=ResumoCusto!$D14)*(ProjecaoAreas!$I$6:$I$46=ResumoCusto!$D16),ProjecaoAreas!$J$6:$J$46))} -> 11868 | F16: =F$14*F15 -> 7942.248 | G16: =G$14*G15 -> 5446.0884 | H16: =H$14*H15 -> 1662.4953 | I16: =(I$14-Frete!L16)*I15 -> 654.03195 | J16: =J$14*J15 -> 2770.8256 | K16: =K$14*K15 -> 1477.7736 | L16: =L$14*L15 -> 987.24468 | M16: =M$14*M15 -> 646.52596 | N16: =N$14*N15 -> 53.4459 | O16: =O$14*O15 -> 1059.6196 | P16: =SUM(F16:O16) -> 22700.299 | Q16: =P16/E16*1000 -> 1912.7316
D17: Real Realizar/Realizado | E17: R$ | F17: {=SUM(IF((Tabela_GM_PEDIDOS_2017_FIM[MOEDA]=$E17)*(Tabela_GM_PEDIDOS_2017_FIM[FILIAL]=$D$14)*(Tabela_GM_PEDIDOS_2017_FIM[TIPO_GRUPO]=F$10),Tabela_GM_PEDIDOS_2017_FIM[VALOR_PAGAR]+Tabela_GM_PEDIDOS_2017_FIM[VC_FINANCEIRA]))*F15/1000} -> 1.7690299 | G17: {=SUM(IF((Tabela_GM_PEDIDOS_2017_FIM[MOEDA]=$E17)*(Tabela_GM_PEDIDOS_2017_FIM[FILIAL]=$D$14)*(Tabela_GM_PEDIDOS_2017_FIM[TIPO_GRUPO]=G$10),Tabela_GM_PEDIDOS_2017_FIM[VALOR_PAGAR]+Tabela_GM_PEDIDOS_2017_FIM[VC_FINANCEIRA]))*G15/1000} -> 708.88491 | H17: {=SUM(IF((Tabela_GM_PEDIDOS_2017_FIM[MOEDA]=$E17)*(Tabela_GM_PEDIDOS_2017_FIM[FILIAL]=$D$14)*(Tabela_GM_PEDIDOS_2017_FIM[TIPO_GRUPO]=H$10),Tabela_GM_PEDIDOS_2017_FIM[VALOR_PAGAR]+Tabela_GM_PEDIDOS_2017_FIM[VC_FINANCEIRA]))*H15/1000} -> 0 | I17: {=SUM(IF((Tabela_GM_PEDIDOS_2017_FIM[MOEDA]=$E17)*(Tabela_GM_PEDIDOS_2017_FIM[FILIAL]=$D$14)*(Tabela_GM_PEDIDOS_2017_FIM[TIPO_GRUPO]=I$10),Tabela_GM_PEDIDOS_2017_FIM[VALOR_PAGAR]+Tabela_GM_PEDIDOS_2017_FIM[VC_FINANCEIRA]))*I15/1000} -> 0 | J17: {=SUM(IF((Tabela_GM_PEDIDOS_2017_FIM[MOEDA]=$E17)*(Tabela_GM_PEDIDOS_2017_FIM[FILIAL]=$D$14)*(Tabela_GM_PEDIDOS_2017_FIM[TIPO_GRUPO]=J$10),Tabela_GM_PEDIDOS_2017_FIM[VALOR_PAGAR]+Tabela_GM_PEDIDOS_2017_FIM[VC_FINANCEIRA]))*J15/1000} -> 0 | K17: {=SUM(IF((Tabela_GM_PEDIDOS_2017_FIM[MOEDA]=$E17)*(Tabela_GM_PEDIDOS_2017_FIM[FILIAL]=$D$14)*(Tabela_GM_PEDIDOS_2017_FIM[TIPO_GRUPO]=K$10),Tabela_GM_PEDIDOS_2017_FIM[VALOR_PAGAR]+Tabela_GM_PEDIDOS_2017_FIM[VC_FINANCEIRA]))*K15/1000} -> 0 | L17: {=SUM(IF((Tabela_GM_PEDIDOS_2017_FIM[MOEDA]=$E17)*(Tabela_GM_PEDIDOS_2017_FIM[FILIAL]=$D$14)*(Tabela_GM_PEDIDOS_2017_FIM[TIPO_GRUPO]=L$10),Tabela_GM_PEDIDOS_2017_FIM[VALOR_PAGAR]+Tabela_GM_PEDIDOS_2017_FIM[VC_FINANCEIRA]))*L15/1000} -> 617.80127 | M17: {=SUM(IF((Tabela_GM_PEDIDOS_2017_FIM[MOEDA]=$E17)*(Tabela_GM_PEDIDOS_2017_FIM[FILIAL]=$D$14)*(Tabela_GM_PEDIDOS_2017_FIM[TIPO_GRUPO]=M$10),Tabela_GM_PEDIDOS_2017_FIM[VALOR_PAGAR]+Tabela_GM_PEDIDOS_2017_FIM[VC_FINANCEIRA]))*M15/1000} -> 0 | ... O17: {=SUM(IF((Tabela_GM_PEDIDOS_2017_FIM[MOEDA]=$E17)*(Tabela_GM_PEDIDOS_2017_FIM[FILIAL]=$D$14)*(Tabela_GM_PEDIDOS_2017_FIM[TIPO_GRUPO]=O$10),Tabela_GM_PEDIDOS_2017_FIM[VALOR_PAGAR]+Tabela_GM_PEDIDOS_2017_FIM[VC_FINANCEIRA]))*O15/1000} -> 6.7058412 | P17: {=SUM(F17:O17)} -> 1388.607
D18: Dolar Realizado | E18: US$ | F18: {=SUM(IF((Tabela_GM_PEDIDOS_2017_FIM[MOEDA]=$E18)*(Tabela_GM_PEDIDOS_2017_FIM[FILIAL]=$D$14)*(Tabela_GM_PEDIDOS_2017_FIM[TIPO_GRUPO]=F$10)*(Tabela_GM_PEDIDOS_2017_FIM[PAGO]="S"),Tabela_GM_PEDIDOS_2017_FIM[VALOR_PAGAR]+Tabela_GM_PEDIDOS_2017_FIM[VC_FINANCEIRA]))*F15/1000} -> 0 | G18: {=SUM(IF((Tabela_GM_PEDIDOS_2017_FIM[MOEDA]=$E18)*(Tabela_GM_PEDIDOS_2017_FIM[FILIAL]=$D$14)*(Tabela_GM_PEDIDOS_2017_FIM[TIPO_GRUPO]=G$10)*(Tabela_GM_PEDIDOS_2017_FIM[PAGO]="S"),Tabela_GM_PEDIDOS_2017_FIM[VALOR_PAGAR]+Tabela_GM_PEDIDOS_2017_FIM[VC_FINANCEIRA]))*G15/1000} -> 742.50297 | H18: {=SUM(IF((Tabela_GM_PEDIDOS_2017_FIM[MOEDA]=$E18)*(Tabela_GM_PEDIDOS_2017_FIM[FILIAL]=$D$14)*(Tabela_GM_PEDIDOS_2017_FIM[TIPO_GRUPO]=H$10)*(Tabela_GM_PEDIDOS_2017_FIM[PAGO]="S"),Tabela_GM_PEDIDOS_2017_FIM[VALOR_PAGAR]+Tabela_GM_PEDIDOS_2017_FIM[VC_FINANCEIRA]))*H15/1000} -> 0 | I18: {=SUM(IF((Tabela_GM_PEDIDOS_2017_FIM[MOEDA]=$E18)*(Tabela_GM_PEDIDOS_2017_FIM[FILIAL]=$D$14)*(Tabela_GM_PEDIDOS_2017_FIM[TIPO_GRUPO]=I$10)*(Tabela_GM_PEDIDOS_2017_FIM[PAGO]="S"),Tabela_GM_PEDIDOS_2017_FIM[VALOR_PAGAR]+Tabela_GM_PEDIDOS_2017_FIM[VC_FINANCEIRA]))*I15/1000} -> 0 | J18: {=SUM(IF((Tabela_GM_PEDIDOS_2017_FIM[MOEDA]=$E18)*(Tabela_GM_PEDIDOS_2017_FIM[FILIAL]=$D$14)*(Tabela_GM_PEDIDOS_2017_FIM[TIPO_GRUPO]=J$10)*(Tabela_GM_PEDIDOS_2017_FIM[PAGO]="S"),Tabela_GM_PEDIDOS_2017_FIM[VALOR_PAGAR]+Tabela_GM_PEDIDOS_2017_FIM[VC_FINANCEIRA]))*J15/1000} -> 0 | K18: {=SUM(IF((Tabela_GM_PEDIDOS_2017_FIM[MOEDA]=$E18)*(Tabela_GM_PEDIDOS_2017_FIM[FILIAL]=$D$14)*(Tabela_GM_PEDIDOS_2017_FIM[TIPO_GRUPO]=K$10)*(Tabela_GM_PEDIDOS_2017_FIM[PAGO]="S"),Tabela_GM_PEDIDOS_2017_FIM[VALOR_PAGAR]+Tabela_GM_PEDIDOS_2017_FIM[VC_FINANCEIRA]))*K15/1000} -> 0 | L18: {=SUM(IF((Tabela_GM_PEDIDOS_2017_FIM[MOEDA]=$E18)*(Tabela_GM_PEDIDOS_2017_FIM[FILIAL]=$D$14)*(Tabela_GM_PEDIDOS_2017_FIM[TIPO_GRUPO]=L$10)*(Tabela_GM_PEDIDOS_2017_FIM[PAGO]="S"),Tabela_GM_PEDIDOS_2017_FIM[VALOR_PAGAR]+Tabela_GM_PEDIDOS_2017_FIM[VC_FINANCEIRA]))*L15/1000} -> 0 | M18: {=SUM(IF((Tabela_GM_PEDIDOS_2017_FIM[MOEDA]=$E18)*(Tabela_GM_PEDIDOS_2017_FIM[FILIAL]=$D$14)*(Tabela_GM_PEDIDOS_2017_FIM[TIPO_GRUPO]=M$10)*(Tabela_GM_PEDIDOS_2017_FIM[PAGO]="S"),Tabela_GM_PEDIDOS_2017_FIM[VALOR_PAGAR]+Tabela_GM_PEDIDOS_2017_FIM[VC_FINANCEIRA]))*M15/1000} -> 0 | ... O18: {=SUM(IF((Tabela_GM_PEDIDOS_2017_FIM[MOEDA]=$E18)*(Tabela_GM_PEDIDOS_2017_FIM[FILIAL]=$D$14)*(Tabela_GM_PEDIDOS_2017_FIM[TIPO_GRUPO]=O$10)*(Tabela_GM_PEDIDOS_2017_FIM[PAGO]="S"),Tabela_GM_PEDIDOS_2017_FIM[VALOR_PAGAR]+Tabela_GM_PEDIDOS_2017_FIM[VC_FINANCEIRA]))*O15/1000} -> 0 | P18: {=SUM(F18:O18)} -> 742.50297
D19: Dolar Realizar | E19: US$ | F19: {=SUM(IF((Tabela_GM_PEDIDOS_2017_FIM[MOEDA]=$E19)*(Tabela_GM_PEDIDOS_2017_FIM[FILIAL]=$D$14)*(Tabela_GM_PEDIDOS_2017_FIM[TIPO_GRUPO]=F$10)*(Tabela_GM_PEDIDOS_2017_FIM[PAGO]<>"S"),Tabela_GM_PEDIDOS_2017_FIM[VL_PEDIDO_COMPRA]))*F15/1000} -> 1730.8291 | G19: {=SUM(IF((Tabela_GM_PEDIDOS_2017_FIM[MOEDA]=$E19)*(Tabela_GM_PEDIDOS_2017_FIM[FILIAL]=$D$14)*(Tabela_GM_PEDIDOS_2017_FIM[TIPO_GRUPO]=G$10)*(Tabela_GM_PEDIDOS_2017_FIM[PAGO]<>"S"),Tabela_GM_PEDIDOS_2017_FIM[VL_PEDIDO_COMPRA]))*G15/1000} -> 1114.9486 | H19: {=SUM(IF((Tabela_GM_PEDIDOS_2017_FIM[MOEDA]=$E19)*(Tabela_GM_PEDIDOS_2017_FIM[FILIAL]=$D$14)*(Tabela_GM_PEDIDOS_2017_FIM[TIPO_GRUPO]=H$10)*(Tabela_GM_PEDIDOS_2017_FIM[PAGO]<>"S"),Tabela_GM_PEDIDOS_2017_FIM[VL_PEDIDO_COMPRA]))*H15/1000} -> 0 | I19: {=SUM(IF((Tabela_GM_PEDIDOS_2017_FIM[MOEDA]=$E19)*(Tabela_GM_PEDIDOS_2017_FIM[FILIAL]=$D$14)*(Tabela_GM_PEDIDOS_2017_FIM[TIPO_GRUPO]=I$10)*(Tabela_GM_PEDIDOS_2017_FIM[PAGO]<>"S"),Tabela_GM_PEDIDOS_2017_FIM[VL_PEDIDO_COMPRA]))*I15/1000} -> 0 | J19: {=SUM(IF((Tabela_GM_PEDIDOS_2017_FIM[MOEDA]=$E19)*(Tabela_GM_PEDIDOS_2017_FIM[FILIAL]=$D$14)*(Tabela_GM_PEDIDOS_2017_FIM[TIPO_GRUPO]=J$10)*(Tabela_GM_PEDIDOS_2017_FIM[PAGO]<>"S"),Tabela_GM_PEDIDOS_2017_FIM[VL_PEDIDO_COMPRA]))*J15/1000} -> 0 | K19: {=SUM(IF((Tabela_GM_PEDIDOS_2017_FIM[MOEDA]=$E19)*(Tabela_GM_PEDIDOS_2017_FIM[FILIAL]=$D$14)*(Tabela_GM_PEDIDOS_2017_FIM[TIPO_GRUPO]=K$10)*(Tabela_GM_PEDIDOS_2017_FIM[PAGO]<>"S"),Tabela_GM_PEDIDOS_2017_FIM[VL_PEDIDO_COMPRA]))*K15/1000} -> 0 | L19: {=SUM(IF((Tabela_GM_PEDIDOS_2017_FIM[MOEDA]=$E19)*(Tabela_GM_PEDIDOS_2017_FIM[FILIAL]=$D$14)*(Tabela_GM_PEDIDOS_2017_FIM[TIPO_GRUPO]=L$10)*(Tabela_GM_PEDIDOS_2017_FIM[PAGO]<>"S"),Tabela_GM_PEDIDOS_2017_FIM[VL_PEDIDO_COMPRA]))*L15/1000} -> 0 | M19: {=SUM(IF((Tabela_GM_PEDIDOS_2017_FIM[MOEDA]=$E19)*(Tabela_GM_PEDIDOS_2017_FIM[FILIAL]=$D$14)*(Tabela_GM_PEDIDOS_2017_FIM[TIPO_GRUPO]=M$10)*(Tabela_GM_PEDIDOS_2017_FIM[PAGO]<>"S"),Tabela_GM_PEDIDOS_2017_FIM[VL_PEDIDO_COMPRA]))*M15/1000} -> 0 | ... O19: {=SUM(IF((Tabela_GM_PEDIDOS_2017_FIM[MOEDA]=$E19)*(Tabela_GM_PEDIDOS_2017_FIM[FILIAL]=$D$14)*(Tabela_GM_PEDIDOS_2017_FIM[TIPO_GRUPO]=O$10)*(Tabela_GM_PEDIDOS_2017_FIM[PAGO]<>"S"),Tabela_GM_PEDIDOS_2017_FIM[VL_PEDIDO_COMPRA]))*O15/1000} -> 0 | P19: =SUM(F19:O19) -> 2845.7777
D21: % Distribuição | F21: {=SUM(IF((ProjecaoAreas!$H$6:$H$46=ResumoCusto!$D$14)*(ProjecaoAreas!$I$6:$I$46=ResumoCusto!$D22),ProjecaoAreas!$L$6:$L$46))} -> 0.11206575 | G21: {=SUM(IF((ProjecaoAreas!$H$6:$H$46=ResumoCusto!$D$14)*(ProjecaoAreas!$I$6:$I$46=ResumoCusto!$D22),ProjecaoAreas!$L$6:$L$46))} -> 0.11206575 | H21: {=SUM(IF((ProjecaoAreas!$H$6:$H$46=ResumoCusto!$D$14)*(ProjecaoAreas!$I$6:$I$46=ResumoCusto!$D22),ProjecaoAreas!$L$6:$L$46))} -> 0.11206575 | I21: 0.21 | J21: {=SUM(IF((ProjecaoAreas!$H$6:$H$46=ResumoCusto!$D$14)*(ProjecaoAreas!$I$6:$I$46=ResumoCusto!$D22),ProjecaoAreas!$L$6:$L$46))} -> 0.11206575 | K21: {=SUM(IF((ProjecaoAreas!$H$6:$H$46=ResumoCusto!$D$14)*(ProjecaoAreas!$I$6:$I$46=ResumoCusto!$D22),ProjecaoAreas!$L$6:$L$46))} -> 0.11206575 | L21: {=SUM(IF((ProjecaoAreas!$H$6:$H$46=ResumoCusto!$D$14)*(ProjecaoAreas!$I$6:$I$46=ResumoCusto!$D22),ProjecaoAreas!$L$6:$L$46))} -> 0.11206575 | M21: {=SUM(IF((ProjecaoAreas!$H$6:$H$46=ResumoCusto!$D$14)*(ProjecaoAreas!$I$6:$I$46=ResumoCusto!$D22),ProjecaoAreas!$L$6:$L$46))} -> 0.11206575 | N21: {=SUM(IF((ProjecaoAreas!$H$6:$H$46=ResumoCusto!$D$14)*(ProjecaoAreas!$I$6:$I$46=ResumoCusto!$D22),ProjecaoAreas!$L$6:$L$46))} -> 0.11206575 | O21: {=SUM(IF((ProjecaoAreas!$H$6:$H$46=ResumoCusto!$D$14)*(ProjecaoAreas!$I$6:$I$46=ResumoCusto!$D22),ProjecaoAreas!$L$6:$L$46))} -> 0.11206575
D22: MILHO EM GRAOS | E22: {=SUM(IF((ProjecaoAreas!$H$6:$H$46=ResumoCusto!$D$14)*(ProjecaoAreas!$I$6:$I$46=ResumoCusto!$D22),ProjecaoAreas!$J$6:$J$46))} -> 12000 | F22: {=F$14*F21} -> 4818.3507 | G22: {=G$14*G21} -> 3303.997 | H22: =H$14*H21 -> 1008.5917 | I22: =(I$14-Frete!L22)*I21 -> 1941.4118 | J22: =J$14*J21 -> 1680.9862 | K22: =K$14*K21 -> 896.52596 | L22: =L$14*L21 -> 598.93509 | M22: =M$14*M21 -> 392.23011 | N22: =N$14*N21 -> 32.424206 | O22: =O$14*O21 -> 642.843 | P22: =SUM(F22:O22) -> 15316.296 | Q22: =P22/E22*1000 -> 1276.358
D23: Real Realizar/Realizado | E23: R$ | F23: {=SUM(IF((Tabela_GM_PEDIDOS_2017_FIM[MOEDA]=$E23)*(Tabela_GM_PEDIDOS_2017_FIM[FILIAL]=$D$14)*(Tabela_GM_PEDIDOS_2017_FIM[TIPO_GRUPO]=F$10),Tabela_GM_PEDIDOS_2017_FIM[VALOR_PAGAR]+Tabela_GM_PEDIDOS_2017_FIM[VC_FINANCEIRA]))*F21/1000} -> 1.0732234 | G23: {=SUM(IF((Tabela_GM_PEDIDOS_2017_FIM[MOEDA]=$E23)*(Tabela_GM_PEDIDOS_2017_FIM[FILIAL]=$D$14)*(Tabela_GM_PEDIDOS_2017_FIM[TIPO_GRUPO]=G$10),Tabela_GM_PEDIDOS_2017_FIM[VALOR_PAGAR]+Tabela_GM_PEDIDOS_2017_FIM[VC_FINANCEIRA]))*G21/1000} -> 430.06163 | H23: {=SUM(IF((Tabela_GM_PEDIDOS_2017_FIM[MOEDA]=$E23)*(Tabela_GM_PEDIDOS_2017_FIM[FILIAL]=$D$14)*(Tabela_GM_PEDIDOS_2017_FIM[TIPO_GRUPO]=H$10),Tabela_GM_PEDIDOS_2017_FIM[VALOR_PAGAR]+Tabela_GM_PEDIDOS_2017_FIM[VC_FINANCEIRA]))*H21/1000} -> 0 | I23: {=SUM(IF((Tabela_GM_PEDIDOS_2017_FIM[MOEDA]=$E23)*(Tabela_GM_PEDIDOS_2017_FIM[FILIAL]=$D$14)*(Tabela_GM_PEDIDOS_2017_FIM[TIPO_GRUPO]=I$10),Tabela_GM_PEDIDOS_2017_FIM[VALOR_PAGAR]+Tabela_GM_PEDIDOS_2017_FIM[VC_FINANCEIRA]))*I21/1000} -> 0 | J23: {=SUM(IF((Tabela_GM_PEDIDOS_2017_FIM[MOEDA]=$E23)*(Tabela_GM_PEDIDOS_2017_FIM[FILIAL]=$D$14)*(Tabela_GM_PEDIDOS_2017_FIM[TIPO_GRUPO]=J$10),Tabela_GM_PEDIDOS_2017_FIM[VALOR_PAGAR]+Tabela_GM_PEDIDOS_2017_FIM[VC_FINANCEIRA]))*J21/1000} -> 0 | K23: {=SUM(IF((Tabela_GM_PEDIDOS_2017_FIM[MOEDA]=$E23)*(Tabela_GM_PEDIDOS_2017_FIM[FILIAL]=$D$14)*(Tabela_GM_PEDIDOS_2017_FIM[TIPO_GRUPO]=K$10),Tabela_GM_PEDIDOS_2017_FIM[VALOR_PAGAR]+Tabela_GM_PEDIDOS_2017_FIM[VC_FINANCEIRA]))*K21/1000} -> 0 | L23: {=SUM(IF((Tabela_GM_PEDIDOS_2017_FIM[MOEDA]=$E23)*(Tabela_GM_PEDIDOS_2017_FIM[FILIAL]=$D$14)*(Tabela_GM_PEDIDOS_2017_FIM[TIPO_GRUPO]=L$10),Tabela_GM_PEDIDOS_2017_FIM[VALOR_PAGAR]+Tabela_GM_PEDIDOS_2017_FIM[VC_FINANCEIRA]))*L21/1000} -> 374.8036 | M23: {=SUM(IF((Tabela_GM_PEDIDOS_2017_FIM[MOEDA]=$E23)*(Tabela_GM_PEDIDOS_2017_FIM[FILIAL]=$D$14)*(Tabela_GM_PEDIDOS_2017_FIM[TIPO_GRUPO]=M$10),Tabela_GM_PEDIDOS_2017_FIM[VALOR_PAGAR]+Tabela_GM_PEDIDOS_2017_FIM[VC_FINANCEIRA]))*M21/1000} -> 0 | ... O23: {=SUM(IF((Tabela_GM_PEDIDOS_2017_FIM[MOEDA]=$E23)*(Tabela_GM_PEDIDOS_2017_FIM[FILIAL]=$D$14)*(Tabela_GM_PEDIDOS_2017_FIM[TIPO_GRUPO]=O$10),Tabela_GM_PEDIDOS_2017_FIM[VALOR_PAGAR]+Tabela_GM_PEDIDOS_2017_FIM[VC_FINANCEIRA]))*O21/1000} -> 4.0682555 | P23: {=SUM(F23:O23)} -> 842.43092
D24: Dolar Realizado | E24: US$ | F24: {=SUM(IF((Tabela_GM_PEDIDOS_2017_FIM[MOEDA]=$E24)*(Tabela_GM_PEDIDOS_2017_FIM[FILIAL]=$D$14)*(Tabela_GM_PEDIDOS_2017_FIM[TIPO_GRUPO]=F$10)*(Tabela_GM_PEDIDOS_2017_FIM[PAGO]="S"),Tabela_GM_PEDIDOS_2017_FIM[VALOR_PAGAR]+Tabela_GM_PEDIDOS_2017_FIM[VC_FINANCEIRA]))*F21/1000} -> 0 | G24: {=SUM(IF((Tabela_GM_PEDIDOS_2017_FIM[MOEDA]=$E24)*(Tabela_GM_PEDIDOS_2017_FIM[FILIAL]=$D$14)*(Tabela_GM_PEDIDOS_2017_FIM[TIPO_GRUPO]=G$10)*(Tabela_GM_PEDIDOS_2017_FIM[PAGO]="S"),Tabela_GM_PEDIDOS_2017_FIM[VALOR_PAGAR]+Tabela_GM_PEDIDOS_2017_FIM[VC_FINANCEIRA]))*G21/1000} -> 450.45681 | H24: {=SUM(IF((Tabela_GM_PEDIDOS_2017_FIM[MOEDA]=$E24)*(Tabela_GM_PEDIDOS_2017_FIM[FILIAL]=$D$14)*(Tabela_GM_PEDIDOS_2017_FIM[TIPO_GRUPO]=H$10)*(Tabela_GM_PEDIDOS_2017_FIM[PAGO]="S"),Tabela_GM_PEDIDOS_2017_FIM[VALOR_PAGAR]+Tabela_GM_PEDIDOS_2017_FIM[VC_FINANCEIRA]))*H21/1000} -> 0 | I24: {=SUM(IF((Tabela_GM_PEDIDOS_2017_FIM[MOEDA]=$E24)*(Tabela_GM_PEDIDOS_2017_FIM[FILIAL]=$D$14)*(Tabela_GM_PEDIDOS_2017_FIM[TIPO_GRUPO]=I$10)*(Tabela_GM_PEDIDOS_2017_FIM[PAGO]="S"),Tabela_GM_PEDIDOS_2017_FIM[VALOR_PAGAR]+Tabela_GM_PEDIDOS_2017_FIM[VC_FINANCEIRA]))*I21/1000} -> 0 | J24: {=SUM(IF((Tabela_GM_PEDIDOS_2017_FIM[MOEDA]=$E24)*(Tabela_GM_PEDIDOS_2017_FIM[FILIAL]=$D$14)*(Tabela_GM_PEDIDOS_2017_FIM[TIPO_GRUPO]=J$10)*(Tabela_GM_PEDIDOS_2017_FIM[PAGO]="S"),Tabela_GM_PEDIDOS_2017_FIM[VALOR_PAGAR]+Tabela_GM_PEDIDOS_2017_FIM[VC_FINANCEIRA]))*J21/1000} -> 0 | K24: {=SUM(IF((Tabela_GM_PEDIDOS_2017_FIM[MOEDA]=$E24)*(Tabela_GM_PEDIDOS_2017_FIM[FILIAL]=$D$14)*(Tabela_GM_PEDIDOS_2017_FIM[TIPO_GRUPO]=K$10)*(Tabela_GM_PEDIDOS_2017_FIM[PAGO]="S"),Tabela_GM_PEDIDOS_2017_FIM[VALOR_PAGAR]+Tabela_GM_PEDIDOS_2017_FIM[VC_FINANCEIRA]))*K21/1000} -> 0 | L24: {=SUM(IF((Tabela_GM_PEDIDOS_2017_FIM[MOEDA]=$E24)*(Tabela_GM_PEDIDOS_2017_FIM[FILIAL]=$D$14)*(Tabela_GM_PEDIDOS_2017_FIM[TIPO_GRUPO]=L$10)*(Tabela_GM_PEDIDOS_2017_FIM[PAGO]="S"),Tabela_GM_PEDIDOS_2017_FIM[VALOR_PAGAR]+Tabela_GM_PEDIDOS_2017_FIM[VC_FINANCEIRA]))*L21/1000} -> 0 | M24: {=SUM(IF((Tabela_GM_PEDIDOS_2017_FIM[MOEDA]=$E24)*(Tabela_GM_PEDIDOS_2017_FIM[FILIAL]=$D$14)*(Tabela_GM_PEDIDOS_2017_FIM[TIPO_GRUPO]=M$10)*(Tabela_GM_PEDIDOS_2017_FIM[PAGO]="S"),Tabela_GM_PEDIDOS_2017_FIM[VALOR_PAGAR]+Tabela_GM_PEDIDOS_2017_FIM[VC_FINANCEIRA]))*M21/1000} -> 0 | ... O24: {=SUM(IF((Tabela_GM_PEDIDOS_2017_FIM[MOEDA]=$E24)*(Tabela_GM_PEDIDOS_2017_FIM[FILIAL]=$D$14)*(Tabela_GM_PEDIDOS_2017_FIM[TIPO_GRUPO]=O$10)*(Tabela_GM_PEDIDOS_2017_FIM[PAGO]="S"),Tabela_GM_PEDIDOS_2017_FIM[VALOR_PAGAR]+Tabela_GM_PEDIDOS_2017_FIM[VC_FINANCEIRA]))*O21/1000} -> 0 | P24: {=SUM(F24:O24)} -> 450.45681
D25: Dolar Realizar | E25: US$ | F25: {=SUM(IF((Tabela_GM_PEDIDOS_2017_FIM[MOEDA]=$E25)*(Tabela_GM_PEDIDOS_2017_FIM[FILIAL]=$D$14)*(Tabela_GM_PEDIDOS_2017_FIM[TIPO_GRUPO]=F$10)*(Tabela_GM_PEDIDOS_2017_FIM[PAGO]<>"S"),Tabela_GM_PEDIDOS_2017_FIM[VL_PEDIDO_COMPRA]))*F21/1000} -> 1050.048 | G25: {=SUM(IF((Tabela_GM_PEDIDOS_2017_FIM[MOEDA]=$E25)*(Tabela_GM_PEDIDOS_2017_FIM[FILIAL]=$D$14)*(Tabela_GM_PEDIDOS_2017_FIM[TIPO_GRUPO]=G$10)*(Tabela_GM_PEDIDOS_2017_FIM[PAGO]<>"S"),Tabela_GM_PEDIDOS_2017_FIM[VL_PEDIDO_COMPRA]))*G21/1000} -> 676.40968 | H25: {=SUM(IF((Tabela_GM_PEDIDOS_2017_FIM[MOEDA]=$E25)*(Tabela_GM_PEDIDOS_2017_FIM[FILIAL]=$D$14)*(Tabela_GM_PEDIDOS_2017_FIM[TIPO_GRUPO]=H$10)*(Tabela_GM_PEDIDOS_2017_FIM[PAGO]<>"S"),Tabela_GM_PEDIDOS_2017_FIM[VL_PEDIDO_COMPRA]))*H21/1000} -> 0 | I25: {=SUM(IF((Tabela_GM_PEDIDOS_2017_FIM[MOEDA]=$E25)*(Tabela_GM_PEDIDOS_2017_FIM[FILIAL]=$D$14)*(Tabela_GM_PEDIDOS_2017_FIM[TIPO_GRUPO]=I$10)*(Tabela_GM_PEDIDOS_2017_FIM[PAGO]<>"S"),Tabela_GM_PEDIDOS_2017_FIM[VL_PEDIDO_COMPRA]))*I21/1000} -> 0 | J25: {=SUM(IF((Tabela_GM_PEDIDOS_2017_FIM[MOEDA]=$E25)*(Tabela_GM_PEDIDOS_2017_FIM[FILIAL]=$D$14)*(Tabela_GM_PEDIDOS_2017_FIM[TIPO_GRUPO]=J$10)*(Tabela_GM_PEDIDOS_2017_FIM[PAGO]<>"S"),Tabela_GM_PEDIDOS_2017_FIM[VL_PEDIDO_COMPRA]))*J21/1000} -> 0 | K25: {=SUM(IF((Tabela_GM_PEDIDOS_2017_FIM[MOEDA]=$E25)*(Tabela_GM_PEDIDOS_2017_FIM[FILIAL]=$D$14)*(Tabela_GM_PEDIDOS_2017_FIM[TIPO_GRUPO]=K$10)*(Tabela_GM_PEDIDOS_2017_FIM[PAGO]<>"S"),Tabela_GM_PEDIDOS_2017_FIM[VL_PEDIDO_COMPRA]))*K21/1000} -> 0 | L25: {=SUM(IF((Tabela_GM_PEDIDOS_2017_FIM[MOEDA]=$E25)*(Tabela_GM_PEDIDOS_2017_FIM[FILIAL]=$D$14)*(Tabela_GM_PEDIDOS_2017_FIM[TIPO_GRUPO]=L$10)*(Tabela_GM_PEDIDOS_2017_FIM[PAGO]<>"S"),Tabela_GM_PEDIDOS_2017_FIM[VL_PEDIDO_COMPRA]))*L21/1000} -> 0 | M25: {=SUM(IF((Tabela_GM_PEDIDOS_2017_FIM[MOEDA]=$E25)*(Tabela_GM_PEDIDOS_2017_FIM[FILIAL]=$D$14)*(Tabela_GM_PEDIDOS_2017_FIM[TIPO_GRUPO]=M$10)*(Tabela_GM_PEDIDOS_2017_FIM[PAGO]<>"S"),Tabela_GM_PEDIDOS_2017_FIM[VL_PEDIDO_COMPRA]))*M21/1000} -> 0 | ... O25: {=SUM(IF((Tabela_GM_PEDIDOS_2017_FIM[MOEDA]=$E25)*(Tabela_GM_PEDIDOS_2017_FIM[FILIAL]=$D$14)*(Tabela_GM_PEDIDOS_2017_FIM[TIPO_GRUPO]=O$10)*(Tabela_GM_PEDIDOS_2017_FIM[PAGO]<>"S"),Tabela_GM_PEDIDOS_2017_FIM[VL_PEDIDO_COMPRA]))*O21/1000} -> 0 | P25: =SUM(F25:O25) -> 1726.4577
D27: % Distribuição | F27: {=SUM(IF((ProjecaoAreas!$H$6:$H$46=ResumoCusto!$D$14)*(ProjecaoAreas!$I$6:$I$46=ResumoCusto!$D28),ProjecaoAreas!$L$6:$L$46))} -> 0.015564687 | G27: {=SUM(IF((ProjecaoAreas!$H$6:$H$46=ResumoCusto!$D$14)*(ProjecaoAreas!$I$6:$I$46=ResumoCusto!$D28),ProjecaoAreas!$L$6:$L$46))} -> 0.015564687 | H27: {=SUM(IF((ProjecaoAreas!$H$6:$H$46=ResumoCusto!$D$14)*(ProjecaoAreas!$I$6:$I$46=ResumoCusto!$D28),ProjecaoAreas!$L$6:$L$46))} -> 0.015564687 | I27: 0.029 | J27: {=SUM(IF((ProjecaoAreas!$H$6:$H$46=ResumoCusto!$D$14)*(ProjecaoAreas!$I$6:$I$46=ResumoCusto!$D28),ProjecaoAreas!$L$6:$L$46))} -> 0.015564687 | K27: {=SUM(IF((ProjecaoAreas!$H$6:$H$46=ResumoCusto!$D$14)*(ProjecaoAreas!$I$6:$I$46=ResumoCusto!$D28),ProjecaoAreas!$L$6:$L$46))} -> 0.015564687 | L27: {=SUM(IF((ProjecaoAreas!$H$6:$H$46=ResumoCusto!$D$14)*(ProjecaoAreas!$I$6:$I$46=ResumoCusto!$D28),ProjecaoAreas!$L$6:$L$46))} -> 0.015564687 | M27: {=SUM(IF((ProjecaoAreas!$H$6:$H$46=ResumoCusto!$D$14)*(ProjecaoAreas!$I$6:$I$46=ResumoCusto!$D28),ProjecaoAreas!$L$6:$L$46))} -> 0.015564687 | N27: {=SUM(IF((ProjecaoAreas!$H$6:$H$46=ResumoCusto!$D$14)*(ProjecaoAreas!$I$6:$I$46=ResumoCusto!$D28),ProjecaoAreas!$L$6:$L$46))} -> 0.015564687 | O27: {=SUM(IF((ProjecaoAreas!$H$6:$H$46=ResumoCusto!$D$14)*(ProjecaoAreas!$I$6:$I$46=ResumoCusto!$D28),ProjecaoAreas!$L$6:$L$46))} -> 0.015564687
D28: SOJA SEMENTE CONVENCIONAL | E28: {=SUM(IF((ProjecaoAreas!$H$6:$H$46=ResumoCusto!$D$14)*(ProjecaoAreas!$I$6:$I$46=ResumoCusto!$D28),ProjecaoAreas!$J$6:$J$46))} -> 1000 | F28: {=F$14*F27} -> 669.21537 | G28: {=G$14*G27} -> 458.88847 | H28: =H$14*H27 -> 140.08218 | I28: =(I$14-Frete!L28)*I27 -> 268.09973 | J28: =J$14*J27 -> 233.4703 | K28: =K$14*K27 -> 124.51749 | L28: =L$14*L27 -> 83.18543 | M28: =M$14*M27 -> 54.476404 | N28: =N$14*N27 -> 4.503362 | O28: =O$14*O27 -> 89.28375 | P28: =SUM(F28:O28) -> 2125.7225 | Q28: =P28/E28*1000 -> 2125.7225
D29: Real Realizar/Realizado | E29: R$ | F29: {=SUM(IF((Tabela_GM_PEDIDOS_2017_FIM[MOEDA]=$E29)*(Tabela_GM_PEDIDOS_2017_FIM[FILIAL]=$D$14)*(Tabela_GM_PEDIDOS_2017_FIM[TIPO_GRUPO]=F$10),Tabela_GM_PEDIDOS_2017_FIM[VALOR_PAGAR]+Tabela_GM_PEDIDOS_2017_FIM[VC_FINANCEIRA]))*F27/1000} -> 0.1490588 | G29: {=SUM(IF((Tabela_GM_PEDIDOS_2017_FIM[MOEDA]=$E29)*(Tabela_GM_PEDIDOS_2017_FIM[FILIAL]=$D$14)*(Tabela_GM_PEDIDOS_2017_FIM[TIPO_GRUPO]=G$10),Tabela_GM_PEDIDOS_2017_FIM[VALOR_PAGAR]+Tabela_GM_PEDIDOS_2017_FIM[VC_FINANCEIRA]))*G27/1000} -> 59.730782 | H29: {=SUM(IF((Tabela_GM_PEDIDOS_2017_FIM[MOEDA]=$E29)*(Tabela_GM_PEDIDOS_2017_FIM[FILIAL]=$D$14)*(Tabela_GM_PEDIDOS_2017_FIM[TIPO_GRUPO]=H$10),Tabela_GM_PEDIDOS_2017_FIM[VALOR_PAGAR]+Tabela_GM_PEDIDOS_2017_FIM[VC_FINANCEIRA]))*H27/1000} -> 0 | I29: {=SUM(IF((Tabela_GM_PEDIDOS_2017_FIM[MOEDA]=$E29)*(Tabela_GM_PEDIDOS_2017_FIM[FILIAL]=$D$14)*(Tabela_GM_PEDIDOS_2017_FIM[TIPO_GRUPO]=I$10),Tabela_GM_PEDIDOS_2017_FIM[VALOR_PAGAR]+Tabela_GM_PEDIDOS_2017_FIM[VC_FINANCEIRA]))*I27/1000} -> 0 | J29: {=SUM(IF((Tabela_GM_PEDIDOS_2017_FIM[MOEDA]=$E29)*(Tabela_GM_PEDIDOS_2017_FIM[FILIAL]=$D$14)*(Tabela_GM_PEDIDOS_2017_FIM[TIPO_GRUPO]=J$10),Tabela_GM_PEDIDOS_2017_FIM[VALOR_PAGAR]+Tabela_GM_PEDIDOS_2017_FIM[VC_FINANCEIRA]))*J27/1000} -> 0 | K29: {=SUM(IF((Tabela_GM_PEDIDOS_2017_FIM[MOEDA]=$E29)*(Tabela_GM_PEDIDOS_2017_FIM[FILIAL]=$D$14)*(Tabela_GM_PEDIDOS_2017_FIM[TIPO_GRUPO]=K$10),Tabela_GM_PEDIDOS_2017_FIM[VALOR_PAGAR]+Tabela_GM_PEDIDOS_2017_FIM[VC_FINANCEIRA]))*K27/1000} -> 0 | L29: {=SUM(IF((Tabela_GM_PEDIDOS_2017_FIM[MOEDA]=$E29)*(Tabela_GM_PEDIDOS_2017_FIM[FILIAL]=$D$14)*(Tabela_GM_PEDIDOS_2017_FIM[TIPO_GRUPO]=L$10),Tabela_GM_PEDIDOS_2017_FIM[VALOR_PAGAR]+Tabela_GM_PEDIDOS_2017_FIM[VC_FINANCEIRA]))*L27/1000} -> 52.056056 | M29: {=SUM(IF((Tabela_GM_PEDIDOS_2017_FIM[MOEDA]=$E29)*(Tabela_GM_PEDIDOS_2017_FIM[FILIAL]=$D$14)*(Tabela_GM_PEDIDOS_2017_FIM[TIPO_GRUPO]=M$10),Tabela_GM_PEDIDOS_2017_FIM[VALOR_PAGAR]+Tabela_GM_PEDIDOS_2017_FIM[VC_FINANCEIRA]))*M27/1000} -> 0 | ... O29: {=SUM(IF((Tabela_GM_PEDIDOS_2017_FIM[MOEDA]=$E29)*(Tabela_GM_PEDIDOS_2017_FIM[FILIAL]=$D$14)*(Tabela_GM_PEDIDOS_2017_FIM[TIPO_GRUPO]=O$10),Tabela_GM_PEDIDOS_2017_FIM[VALOR_PAGAR]+Tabela_GM_PEDIDOS_2017_FIM[VC_FINANCEIRA]))*O27/1000} -> 0.56503549 | P29: {=SUM(F29:O29)} -> 117.00429
D30: Dolar Realizado | E30: US$ | F30: {=SUM(IF((Tabela_GM_PEDIDOS_2017_FIM[MOEDA]=$E30)*(Tabela_GM_PEDIDOS_2017_FIM[FILIAL]=$D$14)*(Tabela_GM_PEDIDOS_2017_FIM[TIPO_GRUPO]=F$10)*(Tabela_GM_PEDIDOS_2017_FIM[PAGO]="S"),Tabela_GM_PEDIDOS_2017_FIM[VALOR_PAGAR]+Tabela_GM_PEDIDOS_2017_FIM[VC_FINANCEIRA]))*F27/1000} -> 0 | G30: {=SUM(IF((Tabela_GM_PEDIDOS_2017_FIM[MOEDA]=$E30)*(Tabela_GM_PEDIDOS_2017_FIM[FILIAL]=$D$14)*(Tabela_GM_PEDIDOS_2017_FIM[TIPO_GRUPO]=G$10)*(Tabela_GM_PEDIDOS_2017_FIM[PAGO]="S"),Tabela_GM_PEDIDOS_2017_FIM[VALOR_PAGAR]+Tabela_GM_PEDIDOS_2017_FIM[VC_FINANCEIRA]))*G27/1000} -> 62.563446 | H30: {=SUM(IF((Tabela_GM_PEDIDOS_2017_FIM[MOEDA]=$E30)*(Tabela_GM_PEDIDOS_2017_FIM[FILIAL]=$D$14)*(Tabela_GM_PEDIDOS_2017_FIM[TIPO_GRUPO]=H$10)*(Tabela_GM_PEDIDOS_2017_FIM[PAGO]="S"),Tabela_GM_PEDIDOS_2017_FIM[VALOR_PAGAR]+Tabela_GM_PEDIDOS_2017_FIM[VC_FINANCEIRA]))*H27/1000} -> 0 | I30: {=SUM(IF((Tabela_GM_PEDIDOS_2017_FIM[MOEDA]=$E30)*(Tabela_GM_PEDIDOS_2017_FIM[FILIAL]=$D$14)*(Tabela_GM_PEDIDOS_2017_FIM[TIPO_GRUPO]=I$10)*(Tabela_GM_PEDIDOS_2017_FIM[PAGO]="S"),Tabela_GM_PEDIDOS_2017_FIM[VALOR_PAGAR]+Tabela_GM_PEDIDOS_2017_FIM[VC_FINANCEIRA]))*I27/1000} -> 0 | J30: {=SUM(IF((Tabela_GM_PEDIDOS_2017_FIM[MOEDA]=$E30)*(Tabela_GM_PEDIDOS_2017_FIM[FILIAL]=$D$14)*(Tabela_GM_PEDIDOS_2017_FIM[TIPO_GRUPO]=J$10)*(Tabela_GM_PEDIDOS_2017_FIM[PAGO]="S"),Tabela_GM_PEDIDOS_2017_FIM[VALOR_PAGAR]+Tabela_GM_PEDIDOS_2017_FIM[VC_FINANCEIRA]))*J27/1000} -> 0 | K30: {=SUM(IF((Tabela_GM_PEDIDOS_2017_FIM[MOEDA]=$E30)*(Tabela_GM_PEDIDOS_2017_FIM[FILIAL]=$D$14)*(Tabela_GM_PEDIDOS_2017_FIM[TIPO_GRUPO]=K$10)*(Tabela_GM_PEDIDOS_2017_FIM[PAGO]="S"),Tabela_GM_PEDIDOS_2017_FIM[VALOR_PAGAR]+Tabela_GM_PEDIDOS_2017_FIM[VC_FINANCEIRA]))*K27/1000} -> 0 | L30: {=SUM(IF((Tabela_GM_PEDIDOS_2017_FIM[MOEDA]=$E30)*(Tabela_GM_PEDIDOS_2017_FIM[FILIAL]=$D$14)*(Tabela_GM_PEDIDOS_2017_FIM[TIPO_GRUPO]=L$10)*(Tabela_GM_PEDIDOS_2017_FIM[PAGO]="S"),Tabela_GM_PEDIDOS_2017_FIM[VALOR_PAGAR]+Tabela_GM_PEDIDOS_2017_FIM[VC_FINANCEIRA]))*L27/1000} -> 0 | M30: {=SUM(IF((Tabela_GM_PEDIDOS_2017_FIM[MOEDA]=$E30)*(Tabela_GM_PEDIDOS_2017_FIM[FILIAL]=$D$14)*(Tabela_GM_PEDIDOS_2017_FIM[TIPO_GRUPO]=M$10)*(Tabela_GM_PEDIDOS_2017_FIM[PAGO]="S"),Tabela_GM_PEDIDOS_2017_FIM[VALOR_PAGAR]+Tabela_GM_PEDIDOS_2017_FIM[VC_FINANCEIRA]))*M27/1000} -> 0 | ... O30: {=SUM(IF((Tabela_GM_PEDIDOS_2017_FIM[MOEDA]=$E30)*(Tabela_GM_PEDIDOS_2017_FIM[FILIAL]=$D$14)*(Tabela_GM_PEDIDOS_2017_FIM[TIPO_GRUPO]=O$10)*(Tabela_GM_PEDIDOS_2017_FIM[PAGO]="S"),Tabela_GM_PEDIDOS_2017_FIM[VALOR_PAGAR]+Tabela_GM_PEDIDOS_2017_FIM[VC_FINANCEIRA]))*O27/1000} -> 0 | P30: {=SUM(F30:O30)} -> 62.563446
D31: Dolar Realizar | E31: US$ | F31: {=SUM(IF((Tabela_GM_PEDIDOS_2017_FIM[MOEDA]=$E31)*(Tabela_GM_PEDIDOS_2017_FIM[FILIAL]=$D$14)*(Tabela_GM_PEDIDOS_2017_FIM[TIPO_GRUPO]=F$10)*(Tabela_GM_PEDIDOS_2017_FIM[PAGO]<>"S"),Tabela_GM_PEDIDOS_2017_FIM[VL_PEDIDO_COMPRA]))*F27/1000} -> 145.84 | G31: {=SUM(IF((Tabela_GM_PEDIDOS_2017_FIM[MOEDA]=$E31)*(Tabela_GM_PEDIDOS_2017_FIM[FILIAL]=$D$14)*(Tabela_GM_PEDIDOS_2017_FIM[TIPO_GRUPO]=G$10)*(Tabela_GM_PEDIDOS_2017_FIM[PAGO]<>"S"),Tabela_GM_PEDIDOS_2017_FIM[VL_PEDIDO_COMPRA]))*G27/1000} -> 93.945788 | H31: {=SUM(IF((Tabela_GM_PEDIDOS_2017_FIM[MOEDA]=$E31)*(Tabela_GM_PEDIDOS_2017_FIM[FILIAL]=$D$14)*(Tabela_GM_PEDIDOS_2017_FIM[TIPO_GRUPO]=H$10)*(Tabela_GM_PEDIDOS_2017_FIM[PAGO]<>"S"),Tabela_GM_PEDIDOS_2017_FIM[VL_PEDIDO_COMPRA]))*H27/1000} -> 0 | I31: {=SUM(IF((Tabela_GM_PEDIDOS_2017_FIM[MOEDA]=$E31)*(Tabela_GM_PEDIDOS_2017_FIM[FILIAL]=$D$14)*(Tabela_GM_PEDIDOS_2017_FIM[TIPO_GRUPO]=I$10)*(Tabela_GM_PEDIDOS_2017_FIM[PAGO]<>"S"),Tabela_GM_PEDIDOS_2017_FIM[VL_PEDIDO_COMPRA]))*I27/1000} -> 0 | J31: {=SUM(IF((Tabela_GM_PEDIDOS_2017_FIM[MOEDA]=$E31)*(Tabela_GM_PEDIDOS_2017_FIM[FILIAL]=$D$14)*(Tabela_GM_PEDIDOS_2017_FIM[TIPO_GRUPO]=J$10)*(Tabela_GM_PEDIDOS_2017_FIM[PAGO]<>"S"),Tabela_GM_PEDIDOS_2017_FIM[VL_PEDIDO_COMPRA]))*J27/1000} -> 0 | K31: {=SUM(IF((Tabela_GM_PEDIDOS_2017_FIM[MOEDA]=$E31)*(Tabela_GM_PEDIDOS_2017_FIM[FILIAL]=$D$14)*(Tabela_GM_PEDIDOS_2017_FIM[TIPO_GRUPO]=K$10)*(Tabela_GM_PEDIDOS_2017_FIM[PAGO]<>"S"),Tabela_GM_PEDIDOS_2017_FIM[VL_PEDIDO_COMPRA]))*K27/1000} -> 0 | L31: {=SUM(IF((Tabela_GM_PEDIDOS_2017_FIM[MOEDA]=$E31)*(Tabela_GM_PEDIDOS_2017_FIM[FILIAL]=$D$14)*(Tabela_GM_PEDIDOS_2017_FIM[TIPO_GRUPO]=L$10)*(Tabela_GM_PEDIDOS_2017_FIM[PAGO]<>"S"),Tabela_GM_PEDIDOS_2017_FIM[VL_PEDIDO_COMPRA]))*L27/1000} -> 0 | M31: {=SUM(IF((Tabela_GM_PEDIDOS_2017_FIM[MOEDA]=$E31)*(Tabela_GM_PEDIDOS_2017_FIM[FILIAL]=$D$14)*(Tabela_GM_PEDIDOS_2017_FIM[TIPO_GRUPO]=M$10)*(Tabela_GM_PEDIDOS_2017_FIM[PAGO]<>"S"),Tabela_GM_PEDIDOS_2017_FIM[VL_PEDIDO_COMPRA]))*M27/1000} -> 0 | ... O31: {=SUM(IF((Tabela_GM_PEDIDOS_2017_FIM[MOEDA]=$E31)*(Tabela_GM_PEDIDOS_2017_FIM[FILIAL]=$D$14)*(Tabela_GM_PEDIDOS_2017_FIM[TIPO_GRUPO]=O$10)*(Tabela_GM_PEDIDOS_2017_FIM[PAGO]<>"S"),Tabela_GM_PEDIDOS_2017_FIM[VL_PEDIDO_COMPRA]))*O27/1000} -> 0 | P31: =SUM(F31:O31) -> 239.78579
D33: % Distribuição | F33: {=SUM(IF((ProjecaoAreas!$H$6:$H$46=ResumoCusto!$D$14)*(ProjecaoAreas!$I$6:$I$46=ResumoCusto!$D34),ProjecaoAreas!$L$6:$L$46))} -> 0.46694061 | G33: {=SUM(IF((ProjecaoAreas!$H$6:$H$46=ResumoCusto!$D$14)*(ProjecaoAreas!$I$6:$I$46=ResumoCusto!$D34),ProjecaoAreas!$L$6:$L$46))} -> 0.46694061 | H33: {=SUM(IF((ProjecaoAreas!$H$6:$H$46=ResumoCusto!$D$14)*(ProjecaoAreas!$I$6:$I$46=ResumoCusto!$D34),ProjecaoAreas!$L$6:$L$46))} -> 0.46694061 | I33: 0 | J33: {=SUM(IF((ProjecaoAreas!$H$6:$H$46=ResumoCusto!$D$14)*(ProjecaoAreas!$I$6:$I$46=ResumoCusto!$D34),ProjecaoAreas!$L$6:$L$46))} -> 0.46694061 | K33: {=SUM(IF((ProjecaoAreas!$H$6:$H$46=ResumoCusto!$D$14)*(ProjecaoAreas!$I$6:$I$46=ResumoCusto!$D34),ProjecaoAreas!$L$6:$L$46))} -> 0.46694061 | L33: {=SUM(IF((ProjecaoAreas!$H$6:$H$46=ResumoCusto!$D$14)*(ProjecaoAreas!$I$6:$I$46=ResumoCusto!$D34),ProjecaoAreas!$L$6:$L$46))} -> 0.46694061 | M33: {=SUM(IF((ProjecaoAreas!$H$6:$H$46=ResumoCusto!$D$14)*(ProjecaoAreas!$I$6:$I$46=ResumoCusto!$D34),ProjecaoAreas!$L$6:$L$46))} -> 0.46694061 | N33: {=SUM(IF((ProjecaoAreas!$H$6:$H$46=ResumoCusto!$D$14)*(ProjecaoAreas!$I$6:$I$46=ResumoCusto!$D34),ProjecaoAreas!$L$6:$L$46))} -> 0.46694061 | O33: {=SUM(IF((ProjecaoAreas!$H$6:$H$46=ResumoCusto!$D$14)*(ProjecaoAreas!$I$6:$I$46=ResumoCusto!$D34),ProjecaoAreas!$L$6:$L$46))} -> 0.46694061
D34: ALGODAO | E34: {=SUM(IF((ProjecaoAreas!$H$6:$H$46=ResumoCusto!$D$14)*(ProjecaoAreas!$I$6:$I$46=ResumoCusto!$D34),ProjecaoAreas!$J$6:$J$46))} -> 8000 | F34: {=F$14*F33} -> 20076.461 | G34: {=G$14*G33} -> 13766.654 | H34: =H$14*H33 -> 4202.4654 | I34: =Frete!K16/1000 -> 7360 | J34: =J$14*J33 -> 7004.1091 | K34: =K$14*K33 -> 3735.5248 | L34: =L$14*L33 -> 2495.5629 | M34: =M$14*M33 -> 1634.2921 | N34: =N$14*N33 -> 135.10086 | O34: =O$14*O33 -> 2678.5125 | P34: =SUM(F34:O34) -> 63088.683 | Q34: =P34/E34*1000 -> 7886.0854
D35: Real Realizar/Realizado | E35: R$ | F35: {=SUM(IF((Tabela_GM_PEDIDOS_2017_FIM[MOEDA]=$E35)*(Tabela_GM_PEDIDOS_2017_FIM[FILIAL]=$D$14)*(Tabela_GM_PEDIDOS_2017_FIM[TIPO_GRUPO]=F$10),Tabela_GM_PEDIDOS_2017_FIM[VALOR_PAGAR]+Tabela_GM_PEDIDOS_2017_FIM[VC_FINANCEIRA]))*F33/1000} -> 4.4717641 | G35: {=SUM(IF((Tabela_GM_PEDIDOS_2017_FIM[MOEDA]=$E35)*(Tabela_GM_PEDIDOS_2017_FIM[FILIAL]=$D$14)*(Tabela_GM_PEDIDOS_2017_FIM[TIPO_GRUPO]=G$10),Tabela_GM_PEDIDOS_2017_FIM[VALOR_PAGAR]+Tabela_GM_PEDIDOS_2017_FIM[VC_FINANCEIRA]))*G33/1000} -> 1791.9234 | H35: {=SUM(IF((Tabela_GM_PEDIDOS_2017_FIM[MOEDA]=$E35)*(Tabela_GM_PEDIDOS_2017_FIM[FILIAL]=$D$14)*(Tabela_GM_PEDIDOS_2017_FIM[TIPO_GRUPO]=H$10),Tabela_GM_PEDIDOS_2017_FIM[VALOR_PAGAR]+Tabela_GM_PEDIDOS_2017_FIM[VC_FINANCEIRA]))*H33/1000} -> 0 | I35: {=SUM(IF((Tabela_GM_PEDIDOS_2017_FIM[MOEDA]=$E35)*(Tabela_GM_PEDIDOS_2017_FIM[FILIAL]=$D$14)*(Tabela_GM_PEDIDOS_2017_FIM[TIPO_GRUPO]=I$10),Tabela_GM_PEDIDOS_2017_FIM[VALOR_PAGAR]+Tabela_GM_PEDIDOS_2017_FIM[VC_FINANCEIRA]))*I33/1000} -> 0 | J35: {=SUM(IF((Tabela_GM_PEDIDOS_2017_FIM[MOEDA]=$E35)*(Tabela_GM_PEDIDOS_2017_FIM[FILIAL]=$D$14)*(Tabela_GM_PEDIDOS_2017_FIM[TIPO_GRUPO]=J$10),Tabela_GM_PEDIDOS_2017_FIM[VALOR_PAGAR]+Tabela_GM_PEDIDOS_2017_FIM[VC_FINANCEIRA]))*J33/1000} -> 0 | K35: {=SUM(IF((Tabela_GM_PEDIDOS_2017_FIM[MOEDA]=$E35)*(Tabela_GM_PEDIDOS_2017_FIM[FILIAL]=$D$14)*(Tabela_GM_PEDIDOS_2017_FIM[TIPO_GRUPO]=K$10),Tabela_GM_PEDIDOS_2017_FIM[VALOR_PAGAR]+Tabela_GM_PEDIDOS_2017_FIM[VC_FINANCEIRA]))*K33/1000} -> 0 | L35: {=SUM(IF((Tabela_GM_PEDIDOS_2017_FIM[MOEDA]=$E35)*(Tabela_GM_PEDIDOS_2017_FIM[FILIAL]=$D$14)*(Tabela_GM_PEDIDOS_2017_FIM[TIPO_GRUPO]=L$10),Tabela_GM_PEDIDOS_2017_FIM[VALOR_PAGAR]+Tabela_GM_PEDIDOS_2017_FIM[VC_FINANCEIRA]))*L33/1000} -> 1561.6817 | M35: {=SUM(IF((Tabela_GM_PEDIDOS_2017_FIM[MOEDA]=$E35)*(Tabela_GM_PEDIDOS_2017_FIM[FILIAL]=$D$14)*(Tabela_GM_PEDIDOS_2017_FIM[TIPO_GRUPO]=M$10),Tabela_GM_PEDIDOS_2017_FIM[VALOR_PAGAR]+Tabela_GM_PEDIDOS_2017_FIM[VC_FINANCEIRA]))*M33/1000} -> 0 | ... O35: {=SUM(IF((Tabela_GM_PEDIDOS_2017_FIM[MOEDA]=$E35)*(Tabela_GM_PEDIDOS_2017_FIM[FILIAL]=$D$14)*(Tabela_GM_PEDIDOS_2017_FIM[TIPO_GRUPO]=O$10),Tabela_GM_PEDIDOS_2017_FIM[VALOR_PAGAR]+Tabela_GM_PEDIDOS_2017_FIM[VC_FINANCEIRA]))*O33/1000} -> 16.951065 | P35: {=SUM(F35:O35)} -> 3510.1288
D36: Dolar Realizado | E36: US$ | F36: {=SUM(IF((Tabela_GM_PEDIDOS_2017_FIM[MOEDA]=$E36)*(Tabela_GM_PEDIDOS_2017_FIM[FILIAL]=$D$14)*(Tabela_GM_PEDIDOS_2017_FIM[TIPO_GRUPO]=F$10)*(Tabela_GM_PEDIDOS_2017_FIM[PAGO]="S"),Tabela_GM_PEDIDOS_2017_FIM[VALOR_PAGAR]+Tabela_GM_PEDIDOS_2017_FIM[VC_FINANCEIRA]))*F33/1000} -> 0 | G36: {=SUM(IF((Tabela_GM_PEDIDOS_2017_FIM[MOEDA]=$E36)*(Tabela_GM_PEDIDOS_2017_FIM[FILIAL]=$D$14)*(Tabela_GM_PEDIDOS_2017_FIM[TIPO_GRUPO]=G$10)*(Tabela_GM_PEDIDOS_2017_FIM[PAGO]="S"),Tabela_GM_PEDIDOS_2017_FIM[VALOR_PAGAR]+Tabela_GM_PEDIDOS_2017_FIM[VC_FINANCEIRA]))*G33/1000} -> 1876.9034 | H36: {=SUM(IF((Tabela_GM_PEDIDOS_2017_FIM[MOEDA]=$E36)*(Tabela_GM_PEDIDOS_2017_FIM[FILIAL]=$D$14)*(Tabela_GM_PEDIDOS_2017_FIM[TIPO_GRUPO]=H$10)*(Tabela_GM_PEDIDOS_2017_FIM[PAGO]="S"),Tabela_GM_PEDIDOS_2017_FIM[VALOR_PAGAR]+Tabela_GM_PEDIDOS_2017_FIM[VC_FINANCEIRA]))*H33/1000} -> 0 | I36: {=SUM(IF((Tabela_GM_PEDIDOS_2017_FIM[MOEDA]=$E36)*(Tabela_GM_PEDIDOS_2017_FIM[FILIAL]=$D$14)*(Tabela_GM_PEDIDOS_2017_FIM[TIPO_GRUPO]=I$10)*(Tabela_GM_PEDIDOS_2017_FIM[PAGO]="S"),Tabela_GM_PEDIDOS_2017_FIM[VALOR_PAGAR]+Tabela_GM_PEDIDOS_2017_FIM[VC_FINANCEIRA]))*I33/1000} -> 0 | J36: {=SUM(IF((Tabela_GM_PEDIDOS_2017_FIM[MOEDA]=$E36)*(Tabela_GM_PEDIDOS_2017_FIM[FILIAL]=$D$14)*(Tabela_GM_PEDIDOS_2017_FIM[TIPO_GRUPO]=J$10)*(Tabela_GM_PEDIDOS_2017_FIM[PAGO]="S"),Tabela_GM_PEDIDOS_2017_FIM[VALOR_PAGAR]+Tabela_GM_PEDIDOS_2017_FIM[VC_FINANCEIRA]))*J33/1000} -> 0 | K36: {=SUM(IF((Tabela_GM_PEDIDOS_2017_FIM[MOEDA]=$E36)*(Tabela_GM_PEDIDOS_2017_FIM[FILIAL]=$D$14)*(Tabela_GM_PEDIDOS_2017_FIM[TIPO_GRUPO]=K$10)*(Tabela_GM_PEDIDOS_2017_FIM[PAGO]="S"),Tabela_GM_PEDIDOS_2017_FIM[VALOR_PAGAR]+Tabela_GM_PEDIDOS_2017_FIM[VC_FINANCEIRA]))*K33/1000} -> 0 | L36: {=SUM(IF((Tabela_GM_PEDIDOS_2017_FIM[MOEDA]=$E36)*(Tabela_GM_PEDIDOS_2017_FIM[FILIAL]=$D$14)*(Tabela_GM_PEDIDOS_2017_FIM[TIPO_GRUPO]=L$10)*(Tabela_GM_PEDIDOS_2017_FIM[PAGO]="S"),Tabela_GM_PEDIDOS_2017_FIM[VALOR_PAGAR]+Tabela_GM_PEDIDOS_2017_FIM[VC_FINANCEIRA]))*L33/1000} -> 0 | M36: {=SUM(IF((Tabela_GM_PEDIDOS_2017_FIM[MOEDA]=$E36)*(Tabela_GM_PEDIDOS_2017_FIM[FILIAL]=$D$14)*(Tabela_GM_PEDIDOS_2017_FIM[TIPO_GRUPO]=M$10)*(Tabela_GM_PEDIDOS_2017_FIM[PAGO]="S"),Tabela_GM_PEDIDOS_2017_FIM[VALOR_PAGAR]+Tabela_GM_PEDIDOS_2017_FIM[VC_FINANCEIRA]))*M33/1000} -> 0 | ... O36: {=SUM(IF((Tabela_GM_PEDIDOS_2017_FIM[MOEDA]=$E36)*(Tabela_GM_PEDIDOS_2017_FIM[FILIAL]=$D$14)*(Tabela_GM_PEDIDOS_2017_FIM[TIPO_GRUPO]=O$10)*(Tabela_GM_PEDIDOS_2017_FIM[PAGO]="S"),Tabela_GM_PEDIDOS_2017_FIM[VALOR_PAGAR]+Tabela_GM_PEDIDOS_2017_FIM[VC_FINANCEIRA]))*O33/1000} -> 0 | P36: {=SUM(F36:O36)} -> 1876.9034
D37: Dolar Realizar | E37: US$ | F37: {=SUM(IF((Tabela_GM_PEDIDOS_2017_FIM[MOEDA]=$E37)*(Tabela_GM_PEDIDOS_2017_FIM[FILIAL]=$D$14)*(Tabela_GM_PEDIDOS_2017_FIM[TIPO_GRUPO]=F$10)*(Tabela_GM_PEDIDOS_2017_FIM[PAGO]<>"S"),Tabela_GM_PEDIDOS_2017_FIM[VL_PEDIDO_COMPRA]))*F33/1000} -> 4375.1999 | G37: {=SUM(IF((Tabela_GM_PEDIDOS_2017_FIM[MOEDA]=$E37)*(Tabela_GM_PEDIDOS_2017_FIM[FILIAL]=$D$14)*(Tabela_GM_PEDIDOS_2017_FIM[TIPO_GRUPO]=G$10)*(Tabela_GM_PEDIDOS_2017_FIM[PAGO]<>"S"),Tabela_GM_PEDIDOS_2017_FIM[VL_PEDIDO_COMPRA]))*G33/1000} -> 2818.3736 | H37: {=SUM(IF((Tabela_GM_PEDIDOS_2017_FIM[MOEDA]=$E37)*(Tabela_GM_PEDIDOS_2017_FIM[FILIAL]=$D$14)*(Tabela_GM_PEDIDOS_2017_FIM[TIPO_GRUPO]=H$10)*(Tabela_GM_PEDIDOS_2017_FIM[PAGO]<>"S"),Tabela_GM_PEDIDOS_2017_FIM[VL_PEDIDO_COMPRA]))*H33/1000} -> 0 | I37: {=SUM(IF((Tabela_GM_PEDIDOS_2017_FIM[MOEDA]=$E37)*(Tabela_GM_PEDIDOS_2017_FIM[FILIAL]=$D$14)*(Tabela_GM_PEDIDOS_2017_FIM[TIPO_GRUPO]=I$10)*(Tabela_GM_PEDIDOS_2017_FIM[PAGO]<>"S"),Tabela_GM_PEDIDOS_2017_FIM[VL_PEDIDO_COMPRA]))*I33/1000} -> 0 | J37: {=SUM(IF((Tabela_GM_PEDIDOS_2017_FIM[MOEDA]=$E37)*(Tabela_GM_PEDIDOS_2017_FIM[FILIAL]=$D$14)*(Tabela_GM_PEDIDOS_2017_FIM[TIPO_GRUPO]=J$10)*(Tabela_GM_PEDIDOS_2017_FIM[PAGO]<>"S"),Tabela_GM_PEDIDOS_2017_FIM[VL_PEDIDO_COMPRA]))*J33/1000} -> 0 | K37: {=SUM(IF((Tabela_GM_PEDIDOS_2017_FIM[MOEDA]=$E37)*(Tabela_GM_PEDIDOS_2017_FIM[FILIAL]=$D$14)*(Tabela_GM_PEDIDOS_2017_FIM[TIPO_GRUPO]=K$10)*(Tabela_GM_PEDIDOS_2017_FIM[PAGO]<>"S"),Tabela_GM_PEDIDOS_2017_FIM[VL_PEDIDO_COMPRA]))*K33/1000} -> 0 | L37: {=SUM(IF((Tabela_GM_PEDIDOS_2017_FIM[MOEDA]=$E37)*(Tabela_GM_PEDIDOS_2017_FIM[FILIAL]=$D$14)*(Tabela_GM_PEDIDOS_2017_FIM[TIPO_GRUPO]=L$10)*(Tabela_GM_PEDIDOS_2017_FIM[PAGO]<>"S"),Tabela_GM_PEDIDOS_2017_FIM[VL_PEDIDO_COMPRA]))*L33/1000} -> 0 | M37: {=SUM(IF((Tabela_GM_PEDIDOS_2017_FIM[MOEDA]=$E37)*(Tabela_GM_PEDIDOS_2017_FIM[FILIAL]=$D$14)*(Tabela_GM_PEDIDOS_2017_FIM[TIPO_GRUPO]=M$10)*(Tabela_GM_PEDIDOS_2017_FIM[PAGO]<>"S"),Tabela_GM_PEDIDOS_2017_FIM[VL_PEDIDO_COMPRA]))*M33/1000} -> 0 | ... O37: {=SUM(IF((Tabela_GM_PEDIDOS_2017_FIM[MOEDA]=$E37)*(Tabela_GM_PEDIDOS_2017_FIM[FILIAL]=$D$14)*(Tabela_GM_PEDIDOS_2017_FIM[TIPO_GRUPO]=O$10)*(Tabela_GM_PEDIDOS_2017_FIM[PAGO]<>"S"),Tabela_GM_PEDIDOS_2017_FIM[VL_PEDIDO_COMPRA]))*O33/1000} -> 0 | P37: =SUM(F37:O37) -> 7193.5736
D39: % Distribuição | F39: {=SUM(IF((ProjecaoAreas!$H$6:$H$46=ResumoCusto!$D$14)*(ProjecaoAreas!$I$6:$I$46=ResumoCusto!$D40),ProjecaoAreas!$L$6:$L$46))} -> 0.17121156 | G39: {=SUM(IF((ProjecaoAreas!$H$6:$H$46=ResumoCusto!$D$14)*(ProjecaoAreas!$I$6:$I$46=ResumoCusto!$D40),ProjecaoAreas!$L$6:$L$46))} -> 0.17121156 | H39: {=SUM(IF((ProjecaoAreas!$H$6:$H$46=ResumoCusto!$D$14)*(ProjecaoAreas!$I$6:$I$46=ResumoCusto!$D40),ProjecaoAreas!$L$6:$L$46))} -> 0.17121156 | I39: 0.321 | J39: {=SUM(IF((ProjecaoAreas!$H$6:$H$46=ResumoCusto!$D$14)*(ProjecaoAreas!$I$6:$I$46=ResumoCusto!$D40),ProjecaoAreas!$L$6:$L$46))} -> 0.17121156 | K39: {=SUM(IF((ProjecaoAreas!$H$6:$H$46=ResumoCusto!$D$14)*(ProjecaoAreas!$I$6:$I$46=ResumoCusto!$D40),ProjecaoAreas!$L$6:$L$46))} -> 0.17121156 | L39: {=SUM(IF((ProjecaoAreas!$H$6:$H$46=ResumoCusto!$D$14)*(ProjecaoAreas!$I$6:$I$46=ResumoCusto!$D40),ProjecaoAreas!$L$6:$L$46))} -> 0.17121156 | M39: {=SUM(IF((ProjecaoAreas!$H$6:$H$46=ResumoCusto!$D$14)*(ProjecaoAreas!$I$6:$I$46=ResumoCusto!$D40),ProjecaoAreas!$L$6:$L$46))} -> 0.17121156 | N39: {=SUM(IF((ProjecaoAreas!$H$6:$H$46=ResumoCusto!$D$14)*(ProjecaoAreas!$I$6:$I$46=ResumoCusto!$D40),ProjecaoAreas!$L$6:$L$46))} -> 0.17121156 | O39: {=SUM(IF((ProjecaoAreas!$H$6:$H$46=ResumoCusto!$D$14)*(ProjecaoAreas!$I$6:$I$46=ResumoCusto!$D40),ProjecaoAreas!$L$6:$L$46))} -> 0.17121156
D40: SOJA CONVENCIONAL | E40: {=SUM(IF((ProjecaoAreas!$H$6:$H$46=ResumoCusto!$D$14)*(ProjecaoAreas!$I$6:$I$46=ResumoCusto!$D40),ProjecaoAreas!$J$6:$J$46))} -> 11000 | F40: {=F$14*F39} -> 7361.3691 | G40: {=G$14*G39} -> 5047.7732 | H40: =H$14*H39 -> 1540.904 | I40: =(I$14-Frete!L40)*I39 -> 2967.5867 | J40: =J$14*J39 -> 2568.1733 | K40: =K$14*K39 -> 1369.6924 | L40: =L$14*L39 -> 915.03973 | M40: =M$14*M39 -> 599.24044 | N40: =N$14*N39 -> 49.536982 | O40: =O$14*O39 -> 982.12126 | P40: =SUM(F40:O40) -> 23401.437 | Q40: =P40/E40*1000 -> 2127.4034
D41: Real Realizar/Realizado | E41: R$ | F41: {=SUM(IF((Tabela_GM_PEDIDOS_2017_FIM[MOEDA]=$E41)*(Tabela_GM_PEDIDOS_2017_FIM[FILIAL]=$D$14)*(Tabela_GM_PEDIDOS_2017_FIM[TIPO_GRUPO]=F$10),Tabela_GM_PEDIDOS_2017_FIM[VALOR_PAGAR]+Tabela_GM_PEDIDOS_2017_FIM[VC_FINANCEIRA]))*F39/1000} -> 1.6396468 | G41: {=SUM(IF((Tabela_GM_PEDIDOS_2017_FIM[MOEDA]=$E41)*(Tabela_GM_PEDIDOS_2017_FIM[FILIAL]=$D$14)*(Tabela_GM_PEDIDOS_2017_FIM[TIPO_GRUPO]=G$10),Tabela_GM_PEDIDOS_2017_FIM[VALOR_PAGAR]+Tabela_GM_PEDIDOS_2017_FIM[VC_FINANCEIRA]))*G39/1000} -> 657.0386 | H41: {=SUM(IF((Tabela_GM_PEDIDOS_2017_FIM[MOEDA]=$E41)*(Tabela_GM_PEDIDOS_2017_FIM[FILIAL]=$D$14)*(Tabela_GM_PEDIDOS_2017_FIM[TIPO_GRUPO]=H$10),Tabela_GM_PEDIDOS_2017_FIM[VALOR_PAGAR]+Tabela_GM_PEDIDOS_2017_FIM[VC_FINANCEIRA]))*H39/1000} -> 0 | I41: {=SUM(IF((Tabela_GM_PEDIDOS_2017_FIM[MOEDA]=$E41)*(Tabela_GM_PEDIDOS_2017_FIM[FILIAL]=$D$14)*(Tabela_GM_PEDIDOS_2017_FIM[TIPO_GRUPO]=I$10),Tabela_GM_PEDIDOS_2017_FIM[VALOR_PAGAR]+Tabela_GM_PEDIDOS_2017_FIM[VC_FINANCEIRA]))*I39/1000} -> 0 | J41: {=SUM(IF((Tabela_GM_PEDIDOS_2017_FIM[MOEDA]=$E41)*(Tabela_GM_PEDIDOS_2017_FIM[FILIAL]=$D$14)*(Tabela_GM_PEDIDOS_2017_FIM[TIPO_GRUPO]=J$10),Tabela_GM_PEDIDOS_2017_FIM[VALOR_PAGAR]+Tabela_GM_PEDIDOS_2017_FIM[VC_FINANCEIRA]))*J39/1000} -> 0 | K41: {=SUM(IF((Tabela_GM_PEDIDOS_2017_FIM[MOEDA]=$E41)*(Tabela_GM_PEDIDOS_2017_FIM[FILIAL]=$D$14)*(Tabela_GM_PEDIDOS_2017_FIM[TIPO_GRUPO]=K$10),Tabela_GM_PEDIDOS_2017_FIM[VALOR_PAGAR]+Tabela_GM_PEDIDOS_2017_FIM[VC_FINANCEIRA]))*K39/1000} -> 0 | L41: {=SUM(IF((Tabela_GM_PEDIDOS_2017_FIM[MOEDA]=$E41)*(Tabela_GM_PEDIDOS_2017_FIM[FILIAL]=$D$14)*(Tabela_GM_PEDIDOS_2017_FIM[TIPO_GRUPO]=L$10),Tabela_GM_PEDIDOS_2017_FIM[VALOR_PAGAR]+Tabela_GM_PEDIDOS_2017_FIM[VC_FINANCEIRA]))*L39/1000} -> 572.61662 | M41: {=SUM(IF((Tabela_GM_PEDIDOS_2017_FIM[MOEDA]=$E41)*(Tabela_GM_PEDIDOS_2017_FIM[FILIAL]=$D$14)*(Tabela_GM_PEDIDOS_2017_FIM[TIPO_GRUPO]=M$10),Tabela_GM_PEDIDOS_2017_FIM[VALOR_PAGAR]+Tabela_GM_PEDIDOS_2017_FIM[VC_FINANCEIRA]))*M39/1000} -> 0 | ... O41: {=SUM(IF((Tabela_GM_PEDIDOS_2017_FIM[MOEDA]=$E41)*(Tabela_GM_PEDIDOS_2017_FIM[FILIAL]=$D$14)*(Tabela_GM_PEDIDOS_2017_FIM[TIPO_GRUPO]=O$10),Tabela_GM_PEDIDOS_2017_FIM[VALOR_PAGAR]+Tabela_GM_PEDIDOS_2017_FIM[VC_FINANCEIRA]))*O39/1000} -> 6.2153904 | P41: {=SUM(F41:O41)} -> 1287.0472
D42: Dolar Realizado | E42: US$ | F42: {=SUM(IF((Tabela_GM_PEDIDOS_2017_FIM[MOEDA]=$E42)*(Tabela_GM_PEDIDOS_2017_FIM[FILIAL]=$D$14)*(Tabela_GM_PEDIDOS_2017_FIM[TIPO_GRUPO]=F$10)*(Tabela_GM_PEDIDOS_2017_FIM[PAGO]="S"),Tabela_GM_PEDIDOS_2017_FIM[VALOR_PAGAR]+Tabela_GM_PEDIDOS_2017_FIM[VC_FINANCEIRA]))*F39/1000} -> 0 | G42: {=SUM(IF((Tabela_GM_PEDIDOS_2017_FIM[MOEDA]=$E42)*(Tabela_GM_PEDIDOS_2017_FIM[FILIAL]=$D$14)*(Tabela_GM_PEDIDOS_2017_FIM[TIPO_GRUPO]=G$10)*(Tabela_GM_PEDIDOS_2017_FIM[PAGO]="S"),Tabela_GM_PEDIDOS_2017_FIM[VALOR_PAGAR]+Tabela_GM_PEDIDOS_2017_FIM[VC_FINANCEIRA]))*G39/1000} -> 688.1979 | H42: {=SUM(IF((Tabela_GM_PEDIDOS_2017_FIM[MOEDA]=$E42)*(Tabela_GM_PEDIDOS_2017_FIM[FILIAL]=$D$14)*(Tabela_GM_PEDIDOS_2017_FIM[TIPO_GRUPO]=H$10)*(Tabela_GM_PEDIDOS_2017_FIM[PAGO]="S"),Tabela_GM_PEDIDOS_2017_FIM[VALOR_PAGAR]+Tabela_GM_PEDIDOS_2017_FIM[VC_FINANCEIRA]))*H39/1000} -> 0 | I42: {=SUM(IF((Tabela_GM_PEDIDOS_2017_FIM[MOEDA]=$E42)*(Tabela_GM_PEDIDOS_2017_FIM[FILIAL]=$D$14)*(Tabela_GM_PEDIDOS_2017_FIM[TIPO_GRUPO]=I$10)*(Tabela_GM_PEDIDOS_2017_FIM[PAGO]="S"),Tabela_GM_PEDIDOS_2017_FIM[VALOR_PAGAR]+Tabela_GM_PEDIDOS_2017_FIM[VC_FINANCEIRA]))*I39/1000} -> 0 | J42: {=SUM(IF((Tabela_GM_PEDIDOS_2017_FIM[MOEDA]=$E42)*(Tabela_GM_PEDIDOS_2017_FIM[FILIAL]=$D$14)*(Tabela_GM_PEDIDOS_2017_FIM[TIPO_GRUPO]=J$10)*(Tabela_GM_PEDIDOS_2017_FIM[PAGO]="S"),Tabela_GM_PEDIDOS_2017_FIM[VALOR_PAGAR]+Tabela_GM_PEDIDOS_2017_FIM[VC_FINANCEIRA]))*J39/1000} -> 0 | K42: {=SUM(IF((Tabela_GM_PEDIDOS_2017_FIM[MOEDA]=$E42)*(Tabela_GM_PEDIDOS_2017_FIM[FILIAL]=$D$14)*(Tabela_GM_PEDIDOS_2017_FIM[TIPO_GRUPO]=K$10)*(Tabela_GM_PEDIDOS_2017_FIM[PAGO]="S"),Tabela_GM_PEDIDOS_2017_FIM[VALOR_PAGAR]+Tabela_GM_PEDIDOS_2017_FIM[VC_FINANCEIRA]))*K39/1000} -> 0 | L42: {=SUM(IF((Tabela_GM_PEDIDOS_2017_FIM[MOEDA]=$E42)*(Tabela_GM_PEDIDOS_2017_FIM[FILIAL]=$D$14)*(Tabela_GM_PEDIDOS_2017_FIM[TIPO_GRUPO]=L$10)*(Tabela_GM_PEDIDOS_2017_FIM[PAGO]="S"),Tabela_GM_PEDIDOS_2017_FIM[VALOR_PAGAR]+Tabela_GM_PEDIDOS_2017_FIM[VC_FINANCEIRA]))*L39/1000} -> 0 | M42: {=SUM(IF((Tabela_GM_PEDIDOS_2017_FIM[MOEDA]=$E42)*(Tabela_GM_PEDIDOS_2017_FIM[FILIAL]=$D$14)*(Tabela_GM_PEDIDOS_2017_FIM[TIPO_GRUPO]=M$10)*(Tabela_GM_PEDIDOS_2017_FIM[PAGO]="S"),Tabela_GM_PEDIDOS_2017_FIM[VALOR_PAGAR]+Tabela_GM_PEDIDOS_2017_FIM[VC_FINANCEIRA]))*M39/1000} -> 0 | ... O42: {=SUM(IF((Tabela_GM_PEDIDOS_2017_FIM[MOEDA]=$E42)*(Tabela_GM_PEDIDOS_2017_FIM[FILIAL]=$D$14)*(Tabela_GM_PEDIDOS_2017_FIM[TIPO_GRUPO]=O$10)*(Tabela_GM_PEDIDOS_2017_FIM[PAGO]="S"),Tabela_GM_PEDIDOS_2017_FIM[VALOR_PAGAR]+Tabela_GM_PEDIDOS_2017_FIM[VC_FINANCEIRA]))*O39/1000} -> 0 | P42: {=SUM(F42:O42)} -> 688.1979
D43: Dolar Realizar | E43: US$ | F43: {=SUM(IF((Tabela_GM_PEDIDOS_2017_FIM[MOEDA]=$E43)*(Tabela_GM_PEDIDOS_2017_FIM[FILIAL]=$D$14)*(Tabela_GM_PEDIDOS_2017_FIM[TIPO_GRUPO]=F$10)*(Tabela_GM_PEDIDOS_2017_FIM[PAGO]<>"S"),Tabela_GM_PEDIDOS_2017_FIM[VL_PEDIDO_COMPRA]))*F39/1000} -> 1604.24 | G43: {=SUM(IF((Tabela_GM_PEDIDOS_2017_FIM[MOEDA]=$E43)*(Tabela_GM_PEDIDOS_2017_FIM[FILIAL]=$D$14)*(Tabela_GM_PEDIDOS_2017_FIM[TIPO_GRUPO]=G$10)*(Tabela_GM_PEDIDOS_2017_FIM[PAGO]<>"S"),Tabela_GM_PEDIDOS_2017_FIM[VL_PEDIDO_COMPRA]))*G39/1000} -> 1033.4037 | H43: {=SUM(IF((Tabela_GM_PEDIDOS_2017_FIM[MOEDA]=$E43)*(Tabela_GM_PEDIDOS_2017_FIM[FILIAL]=$D$14)*(Tabela_GM_PEDIDOS_2017_FIM[TIPO_GRUPO]=H$10)*(Tabela_GM_PEDIDOS_2017_FIM[PAGO]<>"S"),Tabela_GM_PEDIDOS_2017_FIM[VL_PEDIDO_COMPRA]))*H39/1000} -> 0 | I43: {=SUM(IF((Tabela_GM_PEDIDOS_2017_FIM[MOEDA]=$E43)*(Tabela_GM_PEDIDOS_2017_FIM[FILIAL]=$D$14)*(Tabela_GM_PEDIDOS_2017_FIM[TIPO_GRUPO]=I$10)*(Tabela_GM_PEDIDOS_2017_FIM[PAGO]<>"S"),Tabela_GM_PEDIDOS_2017_FIM[VL_PEDIDO_COMPRA]))*I39/1000} -> 0 | J43: {=SUM(IF((Tabela_GM_PEDIDOS_2017_FIM[MOEDA]=$E43)*(Tabela_GM_PEDIDOS_2017_FIM[FILIAL]=$D$14)*(Tabela_GM_PEDIDOS_2017_FIM[TIPO_GRUPO]=J$10)*(Tabela_GM_PEDIDOS_2017_FIM[PAGO]<>"S"),Tabela_GM_PEDIDOS_2017_FIM[VL_PEDIDO_COMPRA]))*J39/1000} -> 0 | K43: {=SUM(IF((Tabela_GM_PEDIDOS_2017_FIM[MOEDA]=$E43)*(Tabela_GM_PEDIDOS_2017_FIM[FILIAL]=$D$14)*(Tabela_GM_PEDIDOS_2017_FIM[TIPO_GRUPO]=K$10)*(Tabela_GM_PEDIDOS_2017_FIM[PAGO]<>"S"),Tabela_GM_PEDIDOS_2017_FIM[VL_PEDIDO_COMPRA]))*K39/1000} -> 0 | L43: {=SUM(IF((Tabela_GM_PEDIDOS_2017_FIM[MOEDA]=$E43)*(Tabela_GM_PEDIDOS_2017_FIM[FILIAL]=$D$14)*(Tabela_GM_PEDIDOS_2017_FIM[TIPO_GRUPO]=L$10)*(Tabela_GM_PEDIDOS_2017_FIM[PAGO]<>"S"),Tabela_GM_PEDIDOS_2017_FIM[VL_PEDIDO_COMPRA]))*L39/1000} -> 0 | M43: {=SUM(IF((Tabela_GM_PEDIDOS_2017_FIM[MOEDA]=$E43)*(Tabela_GM_PEDIDOS_2017_FIM[FILIAL]=$D$14)*(Tabela_GM_PEDIDOS_2017_FIM[TIPO_GRUPO]=M$10)*(Tabela_GM_PEDIDOS_2017_FIM[PAGO]<>"S"),Tabela_GM_PEDIDOS_2017_FIM[VL_PEDIDO_COMPRA]))*M39/1000} -> 0 | ... O43: {=SUM(IF((Tabela_GM_PEDIDOS_2017_FIM[MOEDA]=$E43)*(Tabela_GM_PEDIDOS_2017_FIM[FILIAL]=$D$14)*(Tabela_GM_PEDIDOS_2017_FIM[TIPO_GRUPO]=O$10)*(Tabela_GM_PEDIDOS_2017_FIM[PAGO]<>"S"),Tabela_GM_PEDIDOS_2017_FIM[VL_PEDIDO_COMPRA]))*O39/1000} -> 0 | P43: =SUM(F43:O43) -> 2637.6436
D45: % Distribuição | F45: {=SUM(IF((ProjecaoAreas!$H$6:$H$46=ResumoCusto!$D$14)*(ProjecaoAreas!$I$6:$I$46=ResumoCusto!$D46),ProjecaoAreas!$L$6:$L$46))} -> 0.046694061 | G45: {=SUM(IF((ProjecaoAreas!$H$6:$H$46=ResumoCusto!$D$14)*(ProjecaoAreas!$I$6:$I$46=ResumoCusto!$D46),ProjecaoAreas!$L$6:$L$46))} -> 0.046694061 | H45: {=SUM(IF((ProjecaoAreas!$H$6:$H$46=ResumoCusto!$D$14)*(ProjecaoAreas!$I$6:$I$46=ResumoCusto!$D46),ProjecaoAreas!$L$6:$L$46))} -> 0.046694061 | I45: 0.088 | J45: {=SUM(IF((ProjecaoAreas!$H$6:$H$46=ResumoCusto!$D$14)*(ProjecaoAreas!$I$6:$I$46=ResumoCusto!$D46),ProjecaoAreas!$L$6:$L$46))} -> 0.046694061 | K45: {=SUM(IF((ProjecaoAreas!$H$6:$H$46=ResumoCusto!$D$14)*(ProjecaoAreas!$I$6:$I$46=ResumoCusto!$D46),ProjecaoAreas!$L$6:$L$46))} -> 0.046694061 | L45: {=SUM(IF((ProjecaoAreas!$H$6:$H$46=ResumoCusto!$D$14)*(ProjecaoAreas!$I$6:$I$46=ResumoCusto!$D46),ProjecaoAreas!$L$6:$L$46))} -> 0.046694061 | M45: {=SUM(IF((ProjecaoAreas!$H$6:$H$46=ResumoCusto!$D$14)*(ProjecaoAreas!$I$6:$I$46=ResumoCusto!$D46),ProjecaoAreas!$L$6:$L$46))} -> 0.046694061 | N45: {=SUM(IF((ProjecaoAreas!$H$6:$H$46=ResumoCusto!$D$14)*(ProjecaoAreas!$I$6:$I$46=ResumoCusto!$D46),ProjecaoAreas!$L$6:$L$46))} -> 0.046694061 | O45: {=SUM(IF((ProjecaoAreas!$H$6:$H$46=ResumoCusto!$D$14)*(ProjecaoAreas!$I$6:$I$46=ResumoCusto!$D46),ProjecaoAreas!$L$6:$L$46))} -> 0.046694061
